File: ReFormatted.csv
Time,Displacement,Force,Tensile strain (Strain 1),Tensile stress
(s),(mm),(kN),(%),(MPa)
0,0,0,-0.0016,-0.0002
0.62,0.0178,0.0131,-0.0022,0.624
1.24,0.0387,0.039,-0.0024,1.8589
1.86,0.0594,0.0665,0.0044,3.1686
2.48,0.08,0.0855,0.0051,4.0722
3.1,0.1007,0.1034,0.0104,4.9231
3.72,0.1213,0.1233,0.011,5.8709
4.34,0.1421,0.1444,0.0166,6.8771
4.96,0.1627,0.1661,0.0183,7.9088
5.58,0.1834,0.1882,0.0245,8.9624
6.2,0.2041,0.2099,0.0261,9.9967
6.82,0.2246,0.2309,0.0322,10.9945
7.44,0.2455,0.2516,0.0343,11.983
8.06,0.266,0.2713,0.0396,12.9169
8.68,0.2867,0.2903,0.0408,13.8219
9.3,0.3074,0.3086,0.0467,14.6962
9.92,0.3281,0.3264,0.0478,15.543
10.54,0.3487,0.3441,0.0538,16.3854
11.16,0.3693,0.3637,0.0549,17.3208
11.78,0.3901,0.3822,0.0611,18.1978
12.4,0.4105,0.3988,0.0618,18.989
13.02,0.4314,0.4159,0.0677,19.8032
13.64,0.4519,0.4324,0.0684,20.5924
14.26,0.4726,0.4491,0.074,21.3842
14.88,0.4933,0.4652,0.0747,22.1515
15.5,0.5139,0.4805,0.0809,22.8816
16.12,0.5347,0.496,0.0816,23.6171
16.74,0.5552,0.5111,0.084,24.3362
17.36,0.576,0.5263,0.0876,25.0612
17.98,0.5966,0.5408,0.0887,25.7531
18.6,0.6172,0.5552,0.0941,26.4358
19.22,0.638,0.5698,0.0946,27.1357
19.84,0.6587,0.5838,0.0996,27.801
20.46,0.6794,0.5976,0.0999,28.4559
21.08,0.7,0.6113,0.105,29.1096
21.7,0.7207,0.625,0.1054,29.7624
22.32,0.7413,0.6384,0.1105,30.3981
22.94,0.762,0.6521,0.1108,31.0506
23.56,0.7828,0.6657,0.1162,31.6977
24.18,0.8033,0.6789,0.1164,32.3294
24.8,0.8241,0.6929,0.1221,32.9966
25.42,0.8447,0.7066,0.1224,33.6466
26.04,0.8654,0.7204,0.1281,34.3037
26.66,0.886,0.7337,0.1287,34.9398
27.28,0.9067,0.7474,0.1308,35.5913
27.9,0.9274,0.7611,0.1354,36.2407
28.52,0.948,0.7752,0.1364,36.9136
29.14,0.9688,0.7901,0.1427,37.623
29.76,0.9893,0.8046,0.1436,38.3135
30.38,1.0101,0.8194,0.1468,39.0184
31,1.0307,0.8342,0.1501,39.7257
31.62,1.0514,0.849,0.1517,40.4303
32.24,1.072,0.8638,0.1576,41.1343
32.86,1.0927,0.8784,0.1589,41.8305
33.48,1.1134,0.8928,0.165,42.5139
34.1,1.1339,0.907,0.1659,43.1908
34.72,1.1547,0.9215,0.1701,43.8802
35.34,1.1753,0.9357,0.1732,44.5592
35.96,1.1959,0.95,0.1748,45.2362
36.58,1.2166,0.964,0.181,45.9037
37.2,1.2372,0.9779,0.1819,46.5665
37.82,1.258,0.9922,0.1875,47.2477
38.44,1.2786,1.0057,0.1889,47.8883
39.06,1.2993,1.0197,0.1905,48.5559
39.68,1.32,1.0335,0.1959,49.2143
40.3,1.3406,1.048,0.1972,49.903
40.92,1.3614,1.0625,0.2038,50.5969
41.54,1.382,1.0771,0.2053,51.2919
42.16,1.4027,1.0919,0.2081,51.9971
42.78,1.4233,1.1066,0.2138,52.6969
43.4,1.4441,1.1214,0.2151,53.3995
44.02,1.4646,1.1358,0.2209,54.0876
44.64,1.4854,1.1508,0.2229,54.8009
45.26,1.506,1.1659,0.2268,55.518
45.88,1.5267,1.1808,0.2312,56.2274
46.5,1.5475,1.1958,0.2328,56.9409
47.12,1.568,1.2104,0.2392,57.6393
47.74,1.5887,1.2258,0.2408,58.3692
48.36,1.6093,1.2406,0.2473,59.0771
48.98,1.6301,1.2558,0.2487,59.798
49.6,1.6508,1.2707,0.2513,60.5102
50.22,1.6713,1.2857,0.257,61.2246
50.84,1.6921,1.301,0.2587,61.9521
51.46,1.7127,1.3162,0.2657,62.6749
52.08,1.7334,1.3314,0.2676,63.3982
52.7,1.7541,1.3468,0.2698,64.1356
53.32,1.7747,1.3621,0.277,64.8643
53.94,1.7954,1.3778,0.2786,65.6092
54.56,1.816,1.3929,0.2842,66.3294
55.18,1.8367,1.4082,0.2865,67.0593
55.8,1.8572,1.4231,0.2887,67.7648
56.42,1.878,1.4385,0.295,68.4992
57.04,1.8986,1.4536,0.2969,69.2195
57.66,1.9193,1.4691,0.3037,69.9563
58.28,1.94,1.4847,0.3057,70.7012
58.9,1.9606,1.5002,0.3081,71.4401
59.52,1.9813,1.5162,0.3149,72.1991
60.14,2.0019,1.5314,0.3168,72.9221
60.76,2.0227,1.5472,0.321,73.6784
61.38,2.0433,1.5626,0.3257,74.4107
62,2.0639,1.5781,0.3283,75.148
62.62,2.0847,1.594,0.3345,75.9066
63.24,2.1053,1.6097,0.3378,76.6511
63.86,2.1261,1.6252,0.3398,77.3918
64.48,2.1467,1.6408,0.3467,78.1329
65.1,2.1674,1.6567,0.3489,78.891
65.72,2.1879,1.6718,0.3511,79.6119
66.34,2.2087,1.6873,0.3577,80.3498
66.96,2.2294,1.7028,0.36,81.0868
67.58,2.2499,1.7178,0.3643,81.8012
68.2,2.2708,1.7331,0.3691,82.5295
68.82,2.2914,1.7481,0.3709,83.245
69.44,2.3121,1.7635,0.378,83.9771
70.06,2.3327,1.7791,0.3795,84.7169
70.68,2.3534,1.7951,0.3819,85.4788
71.3,2.3741,1.8108,0.3891,86.2305
71.92,2.3946,1.8267,0.391,86.9864
72.54,2.4155,1.8428,0.397,87.7548
73.16,2.436,1.8587,0.3998,88.5106
73.78,2.4567,1.8749,0.4022,89.2796
74.4,2.4774,1.8911,0.4099,90.0542
75.02,2.498,1.9072,0.412,90.8197
75.64,2.5187,1.9234,0.4142,91.5887
76.26,2.5393,1.9394,0.4214,92.3528
76.88,2.56,1.956,0.4238,93.1444
77.5,2.5806,1.9719,0.4283,93.9021
78.12,2.6014,1.9883,0.4331,94.6821
78.74,2.622,2.0043,0.4357,95.4445
79.36,2.6426,2.0202,0.4418,96.1989
79.98,2.6633,2.0362,0.4449,96.9629
80.6,2.6839,2.0522,0.4478,97.7257
81.22,2.7047,2.0683,0.4538,98.4927
81.84,2.7252,2.0838,0.4572,99.2308
82.46,2.746,2.0997,0.4596,99.9867
83.08,2.7666,2.1154,0.4636,100.7342
83.7,2.7873,2.1312,0.4698,101.4879
84.32,2.8081,2.1474,0.4721,102.2561
84.94,2.8287,2.1632,0.4762,103.0117
85.56,2.8494,2.1791,0.4816,103.7692
86.18,2.87,2.1951,0.4841,104.5283
86.8,2.8908,2.2113,0.487,105.3006
87.42,2.9113,2.227,0.4939,106.0462
88.04,2.9321,2.243,0.4963,106.8075
88.66,2.9528,2.2588,0.4993,107.5641
89.28,2.9733,2.2746,0.5061,108.314
89.9,2.9941,2.2907,0.5084,109.0795
90.501,3.002,2.2875,0.5125,108.9264
91.121,3.0017,2.2751,0.5124,108.34
91.741,3.0015,2.2653,0.5123,107.8693
92.361,3.0015,2.2571,0.5122,107.483
92.981,3.0015,2.2501,0.5122,107.1501
93.601,3.0015,2.2441,0.5122,106.8643
94.221,3.0015,2.2387,0.5122,106.6042
94.841,3.0015,2.2335,0.5122,106.3577
95.461,3.0015,2.2291,0.5122,106.1475
96.081,3.0015,2.2249,0.5122,105.9493
96.701,3.0015,2.2212,0.5122,105.7735
97.321,3.0015,2.2179,0.5122,105.6133
97.893,3.0128,2.2334,0.5188,106.3523
98.513,3.0335,2.2622,0.5309,107.7217
99.133,3.0541,2.2888,0.5429,108.9922
99.753,3.0749,2.3138,0.5551,110.179
100.373,3.0953,2.3369,0.567,111.2793
100.993,3.1162,2.3597,0.5792,112.3648
101.613,3.1369,2.3813,0.5912,113.3951
102.233,3.1574,2.4017,0.6032,114.3655
102.853,3.1781,2.4215,0.6153,115.3092
103.473,3.1988,2.4406,0.6273,116.2177
104.093,3.2195,2.459,0.6394,117.097
104.713,3.2401,2.4769,0.6514,117.9487
105.333,3.2609,2.4943,0.6635,118.7742
105.953,3.2815,2.5114,0.6756,119.5901
106.573,3.302,2.5279,0.6876,120.3742
107.193,3.3228,2.5446,0.6997,121.1709
107.813,3.3434,2.5606,0.7117,121.9352
108.433,3.3641,2.5771,0.7237,122.7183
109.053,3.3847,2.5933,0.7358,123.4923
109.673,3.4054,2.6096,0.7478,124.2671
110.293,3.4261,2.6256,0.7599,125.0286
110.913,3.4467,2.6414,0.7719,125.7823
111.533,3.4674,2.6573,0.784,126.5403
112.153,3.488,2.6727,0.796,127.2718
112.773,3.5087,2.6881,0.8081,128.0031
113.393,3.5294,2.703,0.8201,128.7128
114.013,3.5501,2.7177,0.8322,129.4165
114.633,3.5707,2.732,0.8442,130.0961
115.253,3.5914,2.7462,0.8563,130.7696
115.873,3.6122,2.7604,0.8685,131.4459
116.493,3.6327,2.7738,0.8804,132.0848
117.113,3.6535,2.7877,0.8926,132.7458
117.733,3.6741,2.8012,0.9045,133.3916
118.353,3.6947,2.8138,0.9166,133.9902
118.973,3.7155,2.8119,0.9287,133.8995
0.06,0.0003,0.0003,-0.0005,0.0147
0.68,0.0207,0.0296,0.0049,1.29
1.3,0.0416,0.0672,0.0111,2.9311
1.92,0.0621,0.1061,0.0192,4.6294
2.54,0.0828,0.1448,0.0261,6.3205
3.16,0.1035,0.183,0.034,7.9839
3.78,0.1241,0.2204,0.0413,9.6175
4.4,0.1448,0.2578,0.049,11.2511
5.02,0.1654,0.2948,0.0564,12.863
5.64,0.1862,0.331,0.0634,14.445
6.26,0.2067,0.3655,0.0704,15.9485
6.88,0.2275,0.3992,0.077,17.4192
7.5,0.2482,0.432,0.0835,18.8513
8.12,0.2688,0.4639,0.0898,20.2448
8.74,0.2895,0.495,0.0965,21.5998
9.36,0.3101,0.5252,0.1021,22.9197
9.98,0.3308,0.5549,0.1085,24.214
10.6,0.3514,0.5834,0.1139,25.4586
11.22,0.3722,0.6115,0.1203,26.6832
11.84,0.3928,0.6388,0.1254,27.8759
12.46,0.4133,0.6655,0.1313,29.0388
13.08,0.4342,0.6921,0.1362,30.1996
13.7,0.4547,0.7172,0.1421,31.2976
14.32,0.4754,0.7425,0.147,32.3996
14.94,0.4961,0.7669,0.1528,33.4651
15.56,0.5167,0.7914,0.1577,34.536
16.18,0.5374,0.815,0.1636,35.5664
16.8,0.558,0.8382,0.168,36.5766
17.42,0.5788,0.8607,0.1735,37.5601
18.04,0.5993,0.8824,0.1783,38.5058
18.66,0.6201,0.9038,0.1832,39.4414
19.28,0.6407,0.9248,0.1879,40.3544
19.9,0.6614,0.9454,0.1927,41.2557
20.52,0.682,0.9651,0.1974,42.1147
21.14,0.7028,0.9849,0.2022,42.9774
21.76,0.7235,1.0043,0.2066,43.8257
22.38,0.744,1.0227,0.2114,44.6297
23,0.7648,1.0415,0.2155,45.4489
23.62,0.7854,1.0596,0.2201,46.2363
24.24,0.8061,1.0775,0.2245,47.0195
24.86,0.8268,1.0954,0.2286,47.7989
25.48,0.8475,1.1127,0.2331,48.5564
26.1,0.8682,1.13,0.2368,49.31
26.72,0.8887,1.1469,0.2416,50.0494
27.34,0.9095,1.1644,0.2454,50.8105
27.96,0.9301,1.1812,0.2501,51.5451
28.58,0.9508,1.1982,0.2538,52.2873
29.2,0.9715,1.2151,0.2588,53.0241
29.82,0.9921,1.2317,0.2626,53.7485
30.44,1.0128,1.2485,0.2673,54.4826
31.06,1.0335,1.2651,0.2712,55.2073
31.68,1.0542,1.282,0.2757,55.9443
32.3,1.0748,1.2983,0.2796,56.6558
32.92,1.0955,1.3149,0.2846,57.3794
33.54,1.1161,1.3312,0.2881,58.089
34.16,1.1367,1.3475,0.2928,58.8
34.78,1.1575,1.3643,0.2969,59.5346
35.4,1.178,1.381,0.3015,60.2621
36.02,1.1988,1.398,0.3058,61.0031
36.64,1.2194,1.415,0.3103,61.7483
37.26,1.24,1.4323,0.3148,62.5029
37.88,1.2607,1.4499,0.3192,63.2681
38.5,1.2813,1.4671,0.324,64.0206
39.12,1.3021,1.4846,0.3282,64.7827
39.74,1.3227,1.5017,0.3332,65.5316
40.36,1.3434,1.5193,0.3377,66.2991
40.98,1.3641,1.537,0.343,67.0691
41.6,1.3847,1.5549,0.3474,67.8524
42.22,1.4054,1.5725,0.3527,68.6184
42.84,1.4261,1.5906,0.357,69.4085
43.46,1.4468,1.6087,0.362,70.2004
44.08,1.4674,1.6265,0.367,70.9744
44.7,1.4882,1.6446,0.3713,71.7675
45.32,1.5088,1.6623,0.3766,72.5393
45.94,1.5294,1.6798,0.3811,73.3032
46.56,1.5502,1.6978,0.3866,74.0868
47.18,1.5708,1.7154,0.3911,74.8566
47.8,1.5915,1.7332,0.3962,75.6323
48.42,1.6121,1.7509,0.4006,76.4035
49.04,1.6329,1.7692,0.4055,77.2037
49.66,1.6534,1.7867,0.4108,77.9654
50.28,1.6741,1.8045,0.4154,78.7437
50.9,1.6949,1.8222,0.4208,79.518
51.52,1.7154,1.8396,0.4252,80.2749
52.14,1.7362,1.8575,0.4305,81.0578
52.76,1.7568,1.875,0.4352,81.8191
53.38,1.7775,1.8928,0.4397,82.5981
54,1.7981,1.9106,0.4451,83.3734
54.62,1.8188,1.9286,0.4495,84.1613
55.24,1.8395,1.9463,0.4553,84.9326
55.86,1.86,1.964,0.4597,85.7037
56.48,1.8809,1.9821,0.4642,86.4938
57.1,1.9014,1.9996,0.4696,87.2589
57.72,1.9221,2.018,0.4744,88.0595
58.34,1.9427,2.0359,0.4798,88.8401
58.96,1.9634,2.054,0.4847,89.6304
59.58,1.984,2.0718,0.4901,90.4071
60.2,2.0047,2.0897,0.4948,91.1874
60.82,2.0255,2.108,0.5002,91.988
61.44,2.046,2.1259,0.5054,92.7709
62.06,2.0667,2.1442,0.51,93.5664
62.68,2.0874,2.1622,0.5158,94.3517
63.3,2.1081,2.1804,0.5208,95.1474
63.92,2.1287,2.1984,0.5257,95.9317
64.54,2.1495,2.2165,0.5315,96.7236
65.16,2.1702,2.2347,0.5362,97.515
65.78,2.1907,2.2525,0.5421,98.2948
66.4,2.2115,2.271,0.5471,99.1011
67.02,2.2321,2.2892,0.5527,99.8961
67.64,2.2527,2.3072,0.5577,100.6819
68.26,2.2735,2.3255,0.5631,101.4806
68.88,2.2941,2.3437,0.5688,102.2724
69.5,2.3149,2.3623,0.5739,103.0837
70.12,2.3354,2.3801,0.5795,103.8635
70.74,2.3562,2.3987,0.5851,104.6723
71.36,2.3768,2.4168,0.5898,105.4641
71.98,2.3975,2.4352,0.5958,106.2656
72.6,2.4182,2.4535,0.6007,107.0661
73.22,2.4388,2.4718,0.6066,107.8636
73.84,2.4595,2.4901,0.6116,108.6628
74.46,2.4801,2.5084,0.6174,109.4613
75.08,2.5009,2.5266,0.6224,110.2538
75.7,2.5214,2.5449,0.6276,111.0534
76.32,2.5422,2.5633,0.6333,111.8572
76.94,2.5628,2.5815,0.6383,112.6497
77.56,2.5833,2.5996,0.644,113.4389
78.18,2.6042,2.618,0.649,114.2442
78.8,2.6247,2.636,0.6547,115.0265
79.42,2.6454,2.6541,0.6597,115.818
80.04,2.666,2.6722,0.6657,116.6064
80.66,2.6867,2.6901,0.6707,117.3891
81.28,2.7074,2.7081,0.6759,118.1746
81.9,2.728,2.7259,0.6813,118.9516
82.52,2.7488,2.7439,0.6865,119.7366
83.14,2.7694,2.7615,0.6921,120.5057
83.76,2.79,2.7794,0.697,121.2842
84.38,2.8107,2.7971,0.7028,122.0571
85,2.8314,2.8149,0.708,122.8331
85.62,2.8521,2.8326,0.7138,123.6072
86.24,2.8728,2.8504,0.7186,124.3833
86.86,2.8935,2.8683,0.7243,125.1636
87.48,2.914,2.8857,0.7293,125.923
88.1,2.9348,2.9036,0.7344,126.7037
88.72,2.9554,2.9213,0.7403,127.4777
89.34,2.9761,2.9388,0.7452,128.2397
89.96,2.9968,2.9566,0.7514,129.0191
90.58,3.0174,2.9742,0.7561,129.7886
91.2,3.0382,2.9921,0.7621,130.5687
91.82,3.0587,3.0097,0.7671,131.3351
92.44,3.0795,3.0277,0.7721,132.1203
93.06,3.1001,3.0452,0.7778,132.8866
93.68,3.1208,3.0632,0.7829,133.6684
94.3,3.1415,3.081,0.7889,134.4452
94.92,3.1621,3.0987,0.7939,135.2195
95.54,3.1828,3.1166,0.7994,136.0022
96.16,3.2035,3.1343,0.8048,136.7741
96.78,3.2242,3.1522,0.8105,137.552
97.4,3.2448,3.1699,0.8165,138.3273
98.02,3.2655,3.1875,0.8216,139.095
98.64,3.2861,3.2053,0.8274,139.8691
99.26,3.3067,3.2226,0.8328,140.6273
99.88,3.3275,3.2408,0.8383,141.421
100.5,3.348,3.2582,0.8442,142.1791
101.12,3.3687,3.276,0.8497,142.9569
101.74,3.3894,3.2937,0.8553,143.7305
102.36,3.41,3.3115,0.8612,144.506
102.98,3.4307,3.3295,0.8664,145.2899
103.6,3.4514,3.3472,0.8722,146.0653
104.22,3.4721,3.3651,0.8778,146.846
104.84,3.4927,3.3826,0.8829,147.6064
105.439,3.5017,3.3824,0.8858,147.6002
106.059,3.5014,3.37,0.8856,147.0588
106.679,3.5012,3.36,0.8855,146.6201
107.299,3.5012,3.3515,0.8855,146.2495
107.919,3.5012,3.3439,0.8854,145.9198
108.539,3.5012,3.3369,0.8854,145.6149
109.159,3.5012,3.3305,0.8854,145.3365
109.779,3.5012,3.325,0.8855,145.0946
110.399,3.5012,3.3199,0.8855,144.8701
111.019,3.5012,3.315,0.8855,144.6565
111.605,3.5084,3.3228,0.8897,144.9989
112.225,3.5292,3.3516,0.9018,146.2565
112.845,3.5498,3.3781,0.9138,147.4138
113.465,3.5705,3.4033,0.9259,148.5127
114.085,3.5912,3.4276,0.938,149.5706
114.705,3.6118,3.4506,0.95,150.5752
115.325,3.6325,3.473,0.9621,151.5525
115.945,3.6531,3.4948,0.9741,152.503
116.565,3.6739,3.5162,0.9862,153.4366
117.185,3.6944,3.5366,0.9982,154.3298
117.805,3.7152,3.5571,1.0103,155.2231
118.425,3.7359,3.5769,1.0224,156.0878
119.045,3.7565,3.5962,1.0344,156.9312
119.665,3.7773,3.6158,1.0465,157.7825
120.285,3.7979,3.6344,1.0585,158.5962
120.905,3.8185,3.6529,1.0706,159.4027
121.525,3.8392,3.671,1.0826,160.1943
122.145,3.8599,3.6892,1.0947,160.9863
122.765,3.8806,3.707,1.1067,161.7626
123.385,3.9012,3.7245,1.1188,162.5272
124.005,3.922,3.7423,1.1309,163.3064
124.625,3.9425,3.7592,1.1429,164.0418
125.245,3.9633,3.7765,1.155,164.7979
125.865,3.9839,3.7937,1.167,165.5459
126.485,4.0046,3.8106,1.1791,166.2846
127.105,4.0253,3.8275,1.1911,167.0218
127.725,4.0459,3.8445,1.2032,167.7645
128.345,4.0666,3.8615,1.2153,168.5058
128.965,4.0872,3.8785,1.2272,169.2473
129.585,4.108,3.8957,1.2394,169.999
130.205,4.1286,3.9125,1.2514,170.7327
130.825,4.1492,3.9291,1.2635,171.4552
131.445,4.1699,3.946,1.2755,172.1928
132.065,4.1905,3.9625,1.2875,172.915
132.685,4.2112,3.9794,1.2996,173.6499
133.305,4.2318,3.9961,1.3116,174.3784
133.925,4.2526,4.0127,1.3237,175.1025
134.545,4.2731,4.0292,1.3357,175.8251
135.165,4.2938,4.0459,1.3478,176.5541
135.785,4.3146,4.0629,1.3599,177.2933
136.405,4.3351,4.0792,1.3719,178.0048
137.025,4.3558,4.096,1.384,178.7374
137.645,4.3765,4.1124,1.396,179.455
138.265,4.3972,4.1288,1.4081,180.1695
138.885,4.4178,4.1451,1.4201,180.8796
139.505,4.4385,4.1615,1.4322,181.5964
140.125,4.4593,4.1783,1.4443,182.3302
140.745,4.4798,4.1944,1.4562,183.031
141.365,4.5007,4.2111,1.4684,183.7615
141.985,4.5212,4.2272,1.4804,184.4662
142.605,4.5419,4.2436,1.4924,185.1797
143.225,4.5625,4.26,1.5045,185.8954
143.845,4.5833,4.2765,1.5166,186.616
144.465,4.6039,4.2926,1.5286,187.32
145.085,4.6245,4.3089,1.5407,188.029
145.705,4.6454,4.3256,1.5528,188.759
146.325,4.6658,4.3416,1.5647,189.4544
146.945,4.6866,4.3579,1.5769,190.1669
147.565,4.7073,4.3741,1.5889,190.8751
148.185,4.7279,4.3898,1.601,191.558
148.805,4.7486,4.4052,1.613,192.2334
149.425,4.7693,4.4213,1.6251,192.936
150.045,4.79,4.4375,1.6372,193.641
150.665,4.8105,4.4533,1.6492,194.3297
151.285,4.8314,4.4695,1.6613,195.0372
151.905,4.852,4.4853,1.6733,195.7289
152.525,4.8726,4.5009,1.6853,196.4094
153.145,4.8932,4.517,1.6974,197.1107
153.765,4.9139,4.5325,1.7094,197.7885
154.385,4.9345,4.5484,1.7215,198.4805
155.005,4.9551,4.564,1.7335,199.1629
155.625,4.9759,4.5799,1.7456,199.8562
156.245,4.9965,4.5957,1.7576,200.5461
156.865,5.0171,4.6114,1.7697,201.23
157.485,5.0379,4.6273,1.7818,201.9245
158.105,5.0585,4.6427,1.7938,202.5958
158.725,5.0792,4.6583,1.8059,203.2751
159.345,5.0998,4.6736,1.8179,203.9462
159.965,5.1205,4.689,1.83,204.6177
160.585,5.1411,4.7043,1.842,205.2833
161.205,5.1618,4.7198,1.8541,205.9593
161.825,5.1826,4.7349,1.8662,206.6195
162.445,5.2031,4.7497,1.8781,207.2641
163.065,5.224,4.7646,1.8903,207.9143
163.685,5.2445,4.7791,1.9023,208.5497
164.305,5.2652,4.7936,1.9143,209.1803
164.925,5.2859,4.8081,1.9264,209.8114
165.545,5.3066,4.8226,1.9385,210.4462
166.165,5.3272,4.8364,1.9505,211.0486
166.785,5.3479,4.8504,1.9626,211.6579
167.405,5.3687,4.8645,1.9747,212.2741
168.025,5.3891,4.8774,1.9866,212.8377
168.645,5.4099,4.8912,1.9988,213.4402
169.265,5.4306,4.9045,2.0108,214.0205
169.885,5.4513,4.9163,2.0229,214.5338
170.505,5.4719,4.9237,2.0349,214.859
170.9,5.4853,2.8388,2.0427,123.876
0.28,0.0073,0.0098,-0.0014,0.4582
0.9,0.0281,0.0451,-0.0018,2.1021
1.52,0.0487,0.0836,-0.0011,3.8986
2.14,0.0694,0.1152,-0.0005,5.3713
2.76,0.09,0.1525,0.0004,7.108
3.38,0.1106,0.1892,0.001,8.8177
4,0.1314,0.2244,0.002,10.4631
4.62,0.152,0.2578,0.0023,12.0177
5.24,0.1728,0.2909,0.0019,13.5586
5.86,0.1933,0.3219,0.0004,15.0079
6.48,0.2141,0.3519,-0.0017,16.4029
7.1,0.2347,0.38,-0.0007,17.7164
7.72,0.2554,0.4071,-0.0008,18.9769
8.34,0.2761,0.4326,0,20.1656
8.96,0.2967,0.4564,0.0004,21.2767
9.58,0.3175,0.4803,0.0006,22.3919
10.2,0.338,0.502,0.0017,23.4004
10.82,0.3587,0.5237,0.0024,24.4138
11.44,0.3795,0.5447,0.0035,25.3934
12.06,0.4001,0.5634,0.0024,26.2634
12.68,0.4208,0.5812,-0.0003,27.0938
13.3,0.4414,0.5986,-0.0003,27.9037
13.92,0.4622,0.6152,0.0001,28.6797
14.54,0.4827,0.6375,0.0005,29.7167
15.16,0.5035,0.6648,0.0008,30.9916
15.78,0.5242,0.6914,0.0014,32.2312
16.4,0.5448,0.7169,0.0018,33.4205
17.02,0.5655,0.7416,0.0023,34.5723
17.64,0.5861,0.7655,0.0029,35.6861
18.26,0.6068,0.7884,0.0036,36.7513
18.88,0.6274,0.81,0.0018,37.7583
19.5,0.6482,0.8304,-0.0003,38.7104
20.12,0.6688,0.8489,-0.0002,39.5745
20.74,0.6894,0.8664,0.0003,40.3893
21.36,0.7102,0.8846,0.0009,41.2387
21.98,0.7307,0.9033,0.0017,42.1082
22.6,0.7515,0.922,0.0028,42.9808
23.22,0.772,0.9384,0.0032,43.7449
23.84,0.7928,0.9544,0.0039,44.4899
24.46,0.8133,0.9701,0.0044,45.225
25.08,0.834,0.9863,0.0027,45.9762
25.7,0.8547,1.0029,0.0005,46.7503
26.32,0.8753,1.0193,0.0017,47.5143
26.94,0.8961,1.0363,0.0022,48.3111
27.56,0.9167,1.0533,0.0025,49.0998
28.18,0.9374,1.0702,0.0031,49.8872
28.8,0.958,1.0868,0.0044,50.6626
29.42,0.9788,1.1035,0.0044,51.4399
30.04,0.9995,1.1198,0.0011,52.2027
30.66,1.02,1.1362,0.0017,52.9638
31.28,1.0408,1.1533,0.0024,53.7607
31.9,1.0614,1.1697,0.0034,54.5253
32.52,1.0821,1.1858,0.0046,55.2797
33.14,1.1028,1.2021,0.003,56.0355
33.76,1.1234,1.2182,-0.0039,56.7873
34.38,1.1441,1.2346,-0.0031,57.5543
35,1.1647,1.2512,-0.0031,58.3271
35.62,1.1856,1.2676,-0.0033,59.092
36.24,1.2061,1.2837,-0.0043,59.8425
36.86,1.2268,1.3001,-0.0031,60.6063
37.48,1.2475,1.3164,-0.0028,61.3663
38.1,1.2681,1.3325,-0.0063,62.116
38.72,1.2888,1.3488,-0.0066,62.8782
39.34,1.3094,1.3648,-0.0059,63.6215
39.96,1.3302,1.3808,-0.0055,64.3661
40.58,1.3507,1.3966,-0.0049,65.1048
41.2,1.3715,1.4128,-0.0035,65.8594
41.82,1.3921,1.4291,-0.0068,66.6197
42.44,1.4127,1.4457,-0.0066,67.3917
43.06,1.4335,1.463,-0.0059,68.1994
43.68,1.454,1.4797,-0.0051,68.9794
44.3,1.4747,1.4968,-0.0047,69.7744
44.92,1.4954,1.5139,-0.0042,70.574
45.54,1.5161,1.5312,-0.0037,71.3787
46.16,1.5367,1.5483,-0.0037,72.1768
46.78,1.5573,1.5657,-0.0076,72.9861
47.4,1.5781,1.5833,-0.007,73.8103
48.02,1.5987,1.6006,-0.0064,74.6157
48.64,1.6194,1.6182,-0.006,75.4362
49.26,1.64,1.6356,-0.0048,76.2481
49.88,1.6607,1.6533,-0.0043,77.0708
50.5,1.6813,1.6708,-0.0037,77.8863
51.12,1.7021,1.6883,-0.0059,78.7008
51.74,1.7228,1.7057,-0.0048,79.5127
52.36,1.7434,1.7226,-0.0031,80.3026
52.98,1.7642,1.7399,-0.002,81.1089
53.6,1.7848,1.7567,-0.0012,81.89
54.22,1.8054,1.7735,-0.0001,82.6743
54.84,1.8261,1.7903,-0.0017,83.4585
55.46,1.8468,1.8072,-0.0052,84.2448
56.08,1.8675,1.824,-0.0049,85.0308
56.7,1.888,1.8406,-0.0043,85.8022
57.32,1.9089,1.8579,-0.0039,86.6077
57.94,1.9294,1.8746,-0.0036,87.3863
58.56,1.9501,1.8918,-0.0031,88.1891
59.18,1.9709,1.9091,-0.003,88.9937
59.8,1.9914,1.926,-0.0068,89.7838
60.42,2.0121,1.9435,-0.0061,90.598
61.04,2.0328,1.9609,-0.0054,91.4122
61.66,2.0535,1.9786,-0.0049,92.234
62.28,2.0741,1.9959,-0.0045,93.0401
62.9,2.0949,2.0135,-0.0036,93.8619
63.52,2.1155,2.031,-0.0022,94.6793
64.14,2.136,2.0482,-0.0064,95.4801
64.76,2.1568,2.0661,-0.0055,96.3129
65.38,2.1774,2.0835,-0.005,97.1275
66,2.1981,2.1013,-0.0038,97.9573
66.62,2.2187,2.1192,-0.0032,98.7909
67.24,2.2394,2.1371,-0.0023,99.6236
67.86,2.26,2.155,-0.0017,100.4573
68.48,2.2807,2.1728,-0.0049,101.2893
69.1,2.3014,2.1907,-0.0035,102.1223
69.72,2.322,2.2082,-0.0026,102.9397
70.34,2.3427,2.2258,-0.0014,103.7589
70.96,2.3634,2.2434,0,104.5792
71.58,2.3841,2.2612,-0.0001,105.41
72.2,2.4047,2.2789,-0.0028,106.234
72.82,2.4254,2.2971,-0.0018,107.0833
73.44,2.4462,2.3153,-0.0008,107.9301
74.06,2.4667,2.3329,0.0002,108.7516
74.68,2.4875,2.3511,0.0017,109.5987
75.3,2.5081,2.3689,0.0026,110.4291
75.92,2.5287,2.3868,0.0004,111.2635
76.54,2.5495,2.4047,-0.0003,112.1008
77.16,2.5701,2.4226,0.001,112.9356
77.78,2.5908,2.4405,0.0021,113.7696
78.4,2.6114,2.4581,0.0036,114.5879
79.02,2.6322,2.476,0.0042,115.4234
79.64,2.6527,2.4934,0.0007,116.233
80.26,2.6735,2.5111,0.0016,117.0573
80.88,2.6942,2.5288,0.0024,117.8839
81.5,2.7148,2.5461,0.0034,118.6889
82.12,2.7355,2.5635,0.0046,119.5028
82.74,2.7561,2.5809,0.0051,120.3135
83.36,2.7768,2.5985,0.0066,121.135
83.98,2.7974,2.6157,0.0036,121.9365
84.6,2.8182,2.6333,0.0037,122.7563
85.22,2.8388,2.6505,0.0045,123.5578
85.84,2.8593,2.6678,0.0055,124.3657
86.46,2.8802,2.6854,0.0067,125.1825
87.08,2.9007,2.7026,0.0081,125.9849
87.7,2.9214,2.7204,0.0056,126.8164
88.32,2.9421,2.7378,0.0049,127.6249
88.94,2.9627,2.7555,0.0058,128.4521
89.56,2.9833,2.7731,0.0067,129.2733
90.18,3.004,2.7908,0.0072,130.0963
90.8,3.0248,2.8087,0.0081,130.9328
91.42,3.0453,2.8263,0.0099,131.7526
92.04,3.0661,2.8442,0.0083,132.5863
92.66,3.0867,2.8619,0.0067,133.4103
93.28,3.1074,2.8798,0.0077,134.2453
93.9,3.128,2.8975,0.009,135.0719
94.52,3.1488,2.9154,0.01,135.9084
95.14,3.1695,2.9335,0.0114,136.7478
95.76,3.19,2.951,0.0107,137.5649
96.38,3.2108,2.9693,0.0084,138.4209
97,3.2314,2.9871,0.0091,139.2494
97.62,3.2521,3.005,0.0103,140.0847
98.24,3.2728,3.023,0.0114,140.9198
98.86,3.2934,3.0407,0.0122,141.7483
99.48,3.3141,3.0586,0.0135,142.583
100.1,3.3347,3.0763,0.0099,143.4064
100.72,3.3555,3.0943,0.0101,144.2458
101.34,3.3761,3.1116,0.0109,145.0524
101.96,3.3968,3.1293,0.012,145.8777
102.58,3.4175,3.1469,0.0131,146.6962
103.2,3.4381,3.1638,0.0138,147.4849
103.82,3.4588,3.1811,0.0134,148.294
104.44,3.4795,3.1987,0.0119,149.1145
105.06,3.5002,3.2163,0.0132,149.9339
105.68,3.5207,3.2334,0.014,150.7292
106.3,3.5415,3.251,0.0152,151.5492
106.92,3.5621,3.2681,0.0167,152.3485
107.54,3.5827,3.2851,0.0175,153.1419
108.16,3.6035,3.3028,0.0142,153.964
108.78,3.624,3.3196,0.0151,154.7494
109.4,3.6448,3.337,0.0167,155.5577
110.02,3.6654,3.3541,0.0186,156.3565
110.64,3.686,3.3712,0.0198,157.1538
111.26,3.7067,3.3883,0.0162,157.9526
111.88,3.7273,3.4053,0.0174,158.7422
112.5,3.7481,3.4226,0.0186,159.5509
113.12,3.7686,3.4396,0.0198,160.3411
113.74,3.7894,3.4568,0.021,161.1455
114.36,3.81,3.4739,0.0209,161.9414
114.98,3.8307,3.4911,0.0181,162.7434
115.6,3.8514,3.5082,0.0193,163.5385
116.22,3.8721,3.5249,0.021,164.3187
116.84,3.8929,3.5421,0.0225,165.1219
117.46,3.9134,3.5588,0.0239,165.8987
118.08,3.9342,3.5759,0.0201,166.6956
118.7,3.9548,3.5926,0.0209,167.4755
119.32,3.9754,3.6094,0.022,168.2566
119.94,3.9961,3.6264,0.0231,169.0505
120.56,4.0168,3.6429,0.0243,169.8215
121.18,4.0375,3.6598,0.0221,170.6086
121.8,4.0581,3.676,0.0212,171.363
122.42,4.0788,3.6929,0.0223,172.1525
123.04,4.0994,3.7096,0.0239,172.9313
123.66,4.1201,3.7265,0.0257,173.7183
124.28,4.1409,3.7435,0.0221,174.5092
124.9,4.1614,3.76,0.0233,175.2796
125.52,4.1821,3.777,0.0255,176.0726
126.14,4.2028,3.7937,0.0271,176.8495
126.76,4.2235,3.8106,0.0266,177.6392
127.38,4.2441,3.8273,0.0246,178.4166
128,4.2648,3.8441,0.0256,179.1991
128.62,4.2854,3.8607,0.0269,179.974
129.24,4.306,3.8771,0.0279,180.7361
129.86,4.3268,3.8938,0.0285,181.5178
130.48,4.3473,3.9103,0.0263,182.2846
131.1,4.3681,3.927,0.0275,183.0621
131.72,4.3887,3.9432,0.0286,183.819
132.34,4.4094,3.9596,0.0307,184.5833
132.96,4.43,3.9751,0.0311,185.3052
133.58,4.4506,3.9911,0.03,186.0509
134.2,4.4714,4.0074,0.0322,186.8095
134.82,4.492,4.023,0.0343,187.5403
135.44,4.5127,4.0388,0.0362,188.2775
136.06,4.5334,4.0548,0.0343,189.0195
136.68,4.5541,4.0707,0.036,189.7631
137.3,4.5747,4.0862,0.0376,190.4872
137.92,4.5954,4.102,0.0388,191.2205
138.54,4.6161,4.1179,0.0386,191.9633
139.16,4.6367,4.1334,0.0381,192.6861
139.78,4.6575,4.1492,0.0416,193.4218
140.4,4.6781,4.1644,0.0453,194.1326
141.02,4.6987,4.1801,0.0491,194.8599
141.64,4.7195,4.1953,0.0481,195.569
142.26,4.7401,4.2091,0.0512,196.2144
142.88,4.7608,4.2236,0.0549,196.8907
143.5,4.7814,4.2375,0.0587,197.5362
144.12,4.8022,4.2515,0.0576,198.1923
144.74,4.8228,4.2635,0.0605,198.75
145.36,4.8435,4.2751,0.0629,199.2921
0.06,0.0003,0.0004,0.0015,0.0182
0.68,0.0209,0.0349,-0.0001,1.6424
1.3,0.0414,0.0756,-0.0015,3.5551
1.92,0.0622,0.1177,-0.0032,5.5309
2.54,0.0829,0.1591,0.0001,7.4793
3.16,0.1034,0.1982,-0.0018,9.3129
3.78,0.1242,0.2381,-0.0026,11.1913
4.4,0.1448,0.2777,-0.0015,13.053
5.02,0.1655,0.3171,0.0011,14.9011
5.64,0.1861,0.3555,0.0007,16.709
6.26,0.2068,0.3935,0.0009,18.4925
6.88,0.2275,0.4302,0.0025,20.2164
7.5,0.248,0.4651,0.0085,21.861
8.12,0.2689,0.5002,0.0098,23.5105
8.74,0.2894,0.5338,0.0116,25.0889
9.36,0.3101,0.5671,0.0139,26.6524
9.98,0.3307,0.5992,0.0156,28.16
10.6,0.3514,0.6304,0.0225,29.627
11.22,0.372,0.6605,0.0238,31.0435
11.84,0.3927,0.6895,0.0251,32.4046
12.46,0.4135,0.7177,0.0263,33.7293
13.08,0.434,0.7444,0.0299,34.9861
13.7,0.4548,0.7706,0.0333,36.2173
14.32,0.4754,0.7966,0.0336,37.4369
14.94,0.4961,0.822,0.0344,38.6319
15.56,0.5167,0.8465,0.0364,39.7825
16.18,0.5375,0.8706,0.0396,40.9182
16.8,0.5582,0.8945,0.0389,42.0412
17.42,0.5787,0.9177,0.0392,43.1299
18.04,0.5995,0.9412,0.0402,44.2368
18.66,0.6201,0.9638,0.0456,45.2988
19.28,0.6408,0.9865,0.0459,46.3618
19.9,0.6615,1.0097,0.0464,47.4536
20.52,0.6821,1.0326,0.0474,48.5303
21.14,0.7028,1.0557,0.0536,49.6156
21.76,0.7234,1.0783,0.0566,50.6786
22.38,0.7442,1.1016,0.0585,51.7721
23,0.7648,1.124,0.06,52.8277
23.62,0.7855,1.146,0.0612,53.8618
24.24,0.8062,1.1681,0.0622,54.8973
24.86,0.8268,1.1896,0.0666,55.9077
25.48,0.8475,1.2114,0.0694,56.9326
26.1,0.8681,1.2326,0.0693,57.932
26.72,0.8889,1.2539,0.0685,58.9313
27.34,0.9095,1.2747,0.0676,59.9107
27.96,0.9302,1.2976,0.0708,60.9859
28.58,0.9508,1.3207,0.0702,62.0718
29.2,0.9713,1.3432,0.068,63.1295
29.82,0.9922,1.3657,0.0654,64.1847
30.44,1.0127,1.3873,0.0639,65.1992
31.06,1.0335,1.4085,0.0627,66.1981
31.68,1.054,1.4285,0.0663,67.1379
32.3,1.0747,1.4479,0.0655,68.0474
32.92,1.0954,1.4665,0.0642,68.9211
33.54,1.116,1.4848,0.0631,69.7831
34.16,1.1368,1.5037,0.0625,70.6702
34.78,1.1574,1.5227,0.0618,71.562
35.4,1.1781,1.5421,0.0655,72.4754
36.02,1.1987,1.5608,0.0652,73.354
36.64,1.2194,1.579,0.0639,74.2114
37.26,1.24,1.5974,0.0629,75.0762
37.88,1.2608,1.6161,0.0621,75.9544
38.5,1.2815,1.6349,0.066,76.8376
39.12,1.302,1.6532,0.0645,77.6962
39.74,1.3228,1.6721,0.0634,78.5836
40.36,1.3434,1.6906,0.0626,79.4554
40.98,1.3641,1.7091,0.0624,80.3234
41.6,1.3849,1.7279,0.0653,81.2065
42.22,1.4054,1.746,0.0638,82.0595
42.84,1.4262,1.7647,0.0626,82.9402
43.46,1.4468,1.7834,0.0617,83.8159
44.08,1.4676,1.8023,0.061,84.7062
44.7,1.4881,1.8205,0.0633,85.5597
45.32,1.5088,1.8389,0.0647,86.4269
45.94,1.5296,1.8574,0.0636,87.2937
46.56,1.5501,1.8754,0.0624,88.1393
47.18,1.5709,1.8936,0.0616,88.9949
47.8,1.5915,1.9117,0.0603,89.8444
48.42,1.6122,1.9303,0.0632,90.7186
49.04,1.6328,1.9486,0.0635,91.5819
49.66,1.6535,1.9675,0.0625,92.4686
50.28,1.6741,1.9862,0.0617,93.3493
50.9,1.6947,2.0046,0.061,94.2148
51.52,1.7155,2.0237,0.0603,95.1108
52.14,1.736,2.0424,0.0631,95.9872
52.76,1.7567,2.0614,0.0637,96.8839
53.38,1.7774,2.0804,0.0629,97.7754
54,1.7981,2.0994,0.0622,98.667
54.62,1.8187,2.1186,0.062,99.5716
55.24,1.8394,2.1376,0.0614,100.462
55.86,1.8601,2.1568,0.0625,101.368
56.48,1.8807,2.176,0.0652,102.2666
57.1,1.9014,2.1951,0.0647,103.167
57.72,1.9221,2.2145,0.0645,104.0765
58.34,1.9427,2.2336,0.064,104.9737
58.96,1.9634,2.2528,0.0642,105.8782
59.58,1.9841,2.2721,0.0644,106.7866
60.2,2.0049,2.2917,0.0649,107.7046
60.82,2.0254,2.3105,0.0685,108.5901
61.44,2.0462,2.3299,0.07,109.5036
62.06,2.0668,2.3489,0.0703,110.3951
62.68,2.0874,2.3679,0.0717,111.2886
63.3,2.1082,2.3871,0.0735,112.1906
63.92,2.1288,2.4062,0.0763,113.0871
64.54,2.1495,2.4256,0.0793,114.0002
65.16,2.17,2.4446,0.0829,114.8935
65.78,2.1909,2.4642,0.0906,115.811
66.4,2.2114,2.4832,0.0932,116.7056
67.02,2.2321,2.5023,0.0959,117.6034
67.64,2.2529,2.5215,0.1001,118.5048
68.26,2.2734,2.5405,0.1036,119.3974
68.88,2.2942,2.5598,0.1076,120.3039
69.5,2.3148,2.579,0.1119,121.2075
70.12,2.3355,2.5983,0.1198,122.1157
70.74,2.3561,2.6175,0.1235,123.016
71.36,2.3768,2.6366,0.1272,123.9145
71.98,2.3975,2.6558,0.1312,124.8173
72.6,2.418,2.6746,0.1351,125.7029
73.22,2.4388,2.6941,0.1395,126.616
73.84,2.4594,2.713,0.1435,127.505
74.46,2.4801,2.7324,0.1502,128.4176
75.08,2.5007,2.7515,0.1563,129.3163
75.7,2.5214,2.7709,0.1611,130.2254
76.32,2.5421,2.7901,0.1655,131.129
76.94,2.5627,2.8091,0.1692,132.0222
77.56,2.5835,2.8285,0.173,132.9352
78.18,2.604,2.8475,0.177,133.8276
78.8,2.6247,2.8666,0.1814,134.7242
79.42,2.6454,2.8858,0.1853,135.6255
80.04,2.6661,2.905,0.1899,136.5282
80.66,2.6868,2.9237,0.1949,137.4102
81.28,2.7075,2.9428,0.2018,138.3069
81.9,2.7282,2.9619,0.2075,139.2062
82.52,2.7487,2.9803,0.2124,140.0672
83.14,2.7695,2.9994,0.2164,140.9665
83.76,2.7901,3.0181,0.2203,141.8471
84.38,2.8107,3.0369,0.2243,142.7291
85,2.8315,3.0559,0.2283,143.6235
85.62,2.8521,3.0745,0.232,144.4972
86.24,2.8728,3.0934,0.2367,145.3847
86.86,2.8934,3.1119,0.2412,146.2559
87.48,2.9142,3.1309,0.2484,147.1481
88.1,2.9348,3.1495,0.2544,148.0202
88.72,2.9555,3.1682,0.2587,148.8984
89.34,2.9762,3.1869,0.2641,149.7766
89.96,2.9968,3.2052,0.2689,150.6409
90.58,3.0175,3.2238,0.2734,151.5141
91.2,3.0381,3.2423,0.278,152.3803
91.82,3.0588,3.261,0.2822,153.2608
92.44,3.0795,3.2793,0.2865,154.1238
93.06,3.1002,3.298,0.2914,155.0024
93.68,3.1208,3.3168,0.2957,155.8826
94.3,3.1413,3.3352,0.2998,156.7473
94.92,3.1622,3.354,0.3044,157.6335
95.54,3.1827,3.3721,0.309,158.4826
96.16,3.2034,3.3909,0.3132,159.3671
96.78,3.2241,3.4091,0.3176,160.2241
97.4,3.2447,3.4274,0.322,161.0822
98.02,3.2654,3.4459,0.3303,161.9493
98.64,3.286,3.4641,0.3356,162.8061
99.26,3.3068,3.4824,0.3399,163.6647
99.88,3.3273,3.5005,0.3439,164.5167
100.5,3.3481,3.5189,0.3491,165.3801
101.12,3.3687,3.537,0.3535,166.233
101.74,3.3894,3.5554,0.3583,167.0966
102.36,3.4101,3.5736,0.3628,167.9536
102.98,3.4308,3.5918,0.3672,168.8086
103.6,3.4516,3.6099,0.3737,169.6575
104.22,3.472,3.6275,0.3783,170.4863
104.84,3.4928,3.6458,0.3828,171.3461
105.46,3.5134,3.6636,0.387,172.1811
106.08,3.5341,3.6814,0.3915,173.0175
106.7,3.5548,3.6984,0.3962,173.818
107.32,3.5754,3.7153,0.4011,174.6112
107.94,3.5962,3.7326,0.4086,175.4272
108.56,3.6167,3.7496,0.4137,176.2241
109.18,3.6375,3.7674,0.4181,177.0609
109.8,3.6581,3.7846,0.4218,177.8701
110.42,3.6788,3.8021,0.4249,178.6944
111.04,3.6996,3.8199,0.4284,179.5275
111.66,3.7201,3.8366,0.4321,180.3125
112.28,3.7408,3.8538,0.4359,181.1217
112.9,3.7615,3.8708,0.4394,181.92
113.52,3.7822,3.8877,0.4432,182.7135
114.14,3.8028,3.9042,0.4468,183.4897
114.76,3.8235,3.921,0.4503,184.2811
115.38,3.8441,3.9376,0.4541,185.0622
116,3.8646,3.9536,0.4573,185.8133
116.62,3.8855,3.9701,0.4607,186.5877
117.24,3.906,3.9856,0.4631,187.3164
117.86,3.9268,4.0014,0.468,188.0582
118.48,3.9474,4.0168,0.4735,188.7846
119.1,3.968,4.0293,0.4761,189.3723
119.72,3.9888,4.0337,0.4772,189.5766
120.316,4.002,4.0302,0.4789,189.4123
120.936,4.0016,4.0086,0.4787,188.397
121.556,4.0014,3.9345,0.4786,184.9127
121.791,4.0017,-0.1363,0.4787,-6.4042
122.411,4.0015,0.0253,0.4786,1.1895
123.031,4.0014,0.0256,0.4785,1.2012
123.651,4.0014,0.0309,0.4785,1.4545
124.271,4.0014,0.0195,0.4785,0.916
124.891,4.0014,0.0211,0.4785,0.9928
125.511,4.0014,0.0223,0.4785,1.046
126.131,4.0014,0.0232,0.4785,1.0918
126.751,4.0014,0.0239,0.4785,1.1232
127.371,4.0014,0.0245,0.4785,1.1515
127.991,4.0014,0.025,0.4785,1.1733
128.611,4.0014,0.0254,0.4785,1.1961
129.231,4.0014,0.0258,0.4785,1.211
129.851,4.0014,0.0261,0.4785,1.2272
130.471,4.0014,0.0264,0.4785,1.2407
131.091,4.0014,0.0266,0.4785,1.2494
131.711,4.0014,0.0267,0.4785,1.2552
132.331,4.0014,0.0271,0.4785,1.273
132.951,4.0014,0.0271,0.4785,1.2738
133.571,4.0014,0.0273,0.4785,1.2825
134.191,4.0014,0.0274,0.4785,1.2864
134.811,4.0014,0.0276,0.4785,1.297
135.431,4.0014,0.0277,0.4785,1.3007
136.051,4.0014,0.0278,0.4785,1.3073
136.671,4.0014,0.0279,0.4785,1.31
137.291,4.0014,0.0279,0.4785,1.3121
137.911,4.0014,0.0281,0.4785,1.3215
138.531,4.0014,0.028,0.4785,1.3181
139.151,4.0014,0.0282,0.4785,1.3241
139.771,4.0014,0.0284,0.4785,1.3328
140.391,4.0014,0.0284,0.4785,1.3331
141.011,4.0014,0.0283,0.4785,1.3317
141.631,4.0014,0.0285,0.4785,1.338
142.251,4.0014,0.0285,0.4785,1.3377
142.871,4.0014,0.0285,0.4785,1.341
143.491,4.0014,0.0285,0.4785,1.3406
144.111,4.0014,0.0285,0.4785,1.3411
144.731,4.0014,0.0286,0.4785,1.346
145.351,4.0014,0.0287,0.4785,1.351
145.971,4.0014,0.0287,0.4785,1.349
146.591,4.0014,0.0288,0.4785,1.3535
147.211,4.0014,0.0287,0.4785,1.3476
147.831,4.0014,0.0288,0.4785,1.3526
148.451,4.0014,0.0289,0.4785,1.3567
149.071,4.0014,0.0288,0.4785,1.355
149.691,4.0014,0.0289,0.4785,1.3559
150.311,4.0014,0.0289,0.4785,1.3576
150.931,4.0014,0.0289,0.4785,1.3572
151.533,4.0014,0.029,0.4785,1.3611
152.134,4.0177,0.0362,0.488,1.7006
152.754,4.0385,0.0387,0.5002,1.8176
153.374,4.0591,0.0401,0.5122,1.8827
153.994,4.0798,0.0412,0.5243,1.9361
154.614,4.1005,0.042,0.5363,1.9758
155.234,4.1212,0.0426,0.5484,2.0032
155.854,4.1419,0.0428,0.5605,2.0107
156.474,4.1624,0.0433,0.5724,2.0368
157.094,4.1833,0.0435,0.5846,2.0459
157.714,4.2038,0.0438,0.5966,2.0582
158.334,4.2245,0.0434,0.6086,2.0394
158.954,4.2452,0.0434,0.6207,2.0407
159.574,4.2658,0.0428,0.6327,2.0124
160.194,4.2864,0.0426,0.6448,2.0028
160.814,4.3071,0.0422,0.6568,1.9857
161.434,4.3278,0.0422,0.6689,1.9831
0.2,0.004,0.0145,0.0022,0.2437
0.82,0.0248,0.0928,-0.002,1.5615
1.44,0.0454,0.1646,-0.0012,2.7682
2.06,0.0661,0.2312,-0.0003,3.8887
2.68,0.0867,0.2928,0.0009,4.9244
3.3,0.1074,0.3475,0.0017,5.8449
3.92,0.128,0.3941,-0.0025,6.6294
4.54,0.1487,0.4347,-0.0012,7.312
5.16,0.1694,0.4722,-0.0001,7.9424
5.78,0.19,0.5065,0.0009,8.5192
6.4,0.2107,0.5391,0.0017,9.0684
7.02,0.2313,0.5706,-0.0026,9.5977
7.64,0.2521,0.5987,-0.0018,10.0705
8.26,0.2727,0.6239,-0.0009,10.4951
8.88,0.2934,0.6486,0,10.9102
9.5,0.3141,0.6718,0.0008,11.3
10.12,0.3347,0.6924,0.0001,11.6457
10.74,0.3555,0.7152,-0.002,12.03
11.36,0.376,0.7397,-0.001,12.4418
11.98,0.3968,0.7624,0.0004,12.8239
12.6,0.4174,0.7842,0.0015,13.191
13.22,0.4381,0.8075,-0.0026,13.5828
13.84,0.4588,0.8323,-0.0019,13.9993
14.46,0.4794,0.8585,-0.0013,14.4411
15.08,0.5002,0.887,-0.0005,14.9195
15.7,0.5207,0.9159,0.0009,15.4051
16.32,0.5415,0.9464,-0.0021,15.9192
16.94,0.5622,0.9761,-0.0026,16.4186
17.56,0.5828,1.0066,-0.0015,16.9311
18.18,0.6035,1.038,-0.0001,17.4598
18.8,0.6241,1.0686,0.0012,17.9746
19.42,0.6448,1.0986,-0.003,18.4796
20.04,0.6654,1.1267,-0.0018,18.9513
20.66,0.6862,1.1555,-0.0005,19.4352
21.28,0.7068,1.1842,0.001,19.918
21.9,0.7273,1.2127,-0.0031,20.399
22.52,0.7482,1.2429,-0.0019,20.9062
23.14,0.7687,1.2716,-0.0011,21.3883
23.76,0.7894,1.3003,-0.0002,21.8713
24.38,0.81,1.3294,0.0012,22.3603
25,0.8307,1.3596,-0.0027,22.869
25.62,0.8514,1.39,-0.0016,23.3806
26.24,0.872,1.42,-0.0008,23.8854
26.86,0.8928,1.4507,0.0003,24.4012
27.48,0.9133,1.4797,0.001,24.8898
28.1,0.9341,1.5085,-0.0031,25.3743
28.72,0.9547,1.5374,-0.002,25.8601
29.34,0.9754,1.5656,-0.0013,26.3333
29.96,0.996,1.5934,-0.0001,26.8016
30.58,1.0168,1.6219,0.0002,27.2805
31.2,1.0375,1.6506,-0.0022,27.7636
31.82,1.058,1.6787,-0.0008,28.2371
32.44,1.0788,1.7083,0.0009,28.735
33.06,1.0994,1.7376,-0.0012,29.2269
33.68,1.1201,1.7673,-0.0023,29.7263
34.3,1.1408,1.7971,-0.0011,30.2278
34.92,1.1614,1.8263,-0.0001,30.72
35.54,1.1821,1.8559,0.0014,31.2177
36.16,1.2027,1.8849,-0.0027,31.7056
36.78,1.2235,1.9147,-0.0018,32.2069
37.4,1.2441,1.9438,-0.0007,32.696
38.02,1.2648,1.9734,0.0007,33.1931
38.64,1.2855,2.0028,-0.0003,33.6886
39.26,1.3061,2.0311,-0.0023,34.1639
39.88,1.3268,2.0588,-0.0013,34.6295
40.5,1.3475,2.0849,-0.0002,35.0689
41.12,1.3682,2.1109,0.0012,35.5069
41.74,1.3887,2.1367,-0.0024,35.94
42.36,1.4095,2.1636,-0.0012,36.392
42.98,1.4301,2.19,-0.0004,36.8373
43.6,1.4507,2.217,0.0008,37.2904
44.22,1.4715,2.2447,0.0016,37.7573
44.84,1.492,2.2716,-0.002,38.2085
45.46,1.5128,2.2994,-0.0007,38.6764
46.08,1.5333,2.3265,0.0005,39.1328
46.7,1.5541,2.354,0.0022,39.5951
47.32,1.5747,2.3814,-0.0013,40.056
47.94,1.5953,2.4082,-0.0012,40.5066
48.56,1.6161,2.4355,0.0001,40.9667
49.18,1.6366,2.4622,0.0012,41.4161
49.8,1.6574,2.4895,0.0027,41.8748
50.42,1.678,2.5165,-0.001,42.3285
51.04,1.6987,2.5439,0.0005,42.7898
51.66,1.7193,2.5711,0.0013,43.2463
52.28,1.7401,2.5986,0.003,43.7091
52.9,1.7608,2.626,-0.001,44.171
53.52,1.7814,2.6529,0.0005,44.623
54.14,1.8021,2.6806,0.0013,45.0894
54.76,1.8227,2.7079,0.0029,45.5475
55.38,1.8434,2.735,0.0022,46.0032
56,1.8641,2.7624,-0.0001,46.4648
56.62,1.8847,2.7896,0.0011,46.9224
57.24,1.9055,2.8171,0.0026,47.3852
57.86,1.9261,2.8441,0.0043,47.8392
58.48,1.9469,2.8718,0.0008,48.3045
59.1,1.9674,2.8981,0.0022,48.7469
59.72,1.9881,2.9253,0.0035,49.2048
60.34,2.0089,2.9526,0.0051,49.6634
60.96,2.0294,2.9792,0.0008,50.1113
61.58,2.0502,3.0064,0.0017,50.5688
62.2,2.0708,3.0334,0.003,51.0225
62.82,2.0915,3.0606,0.0045,51.481
63.44,2.1121,3.0873,0.0009,51.9301
64.06,2.1329,3.1146,0.0022,52.3896
64.68,2.1534,3.1415,0.0035,52.8411
65.3,2.174,3.1682,0.0054,53.2898
65.92,2.1948,3.1954,0.0015,53.7473
66.54,2.2153,3.2215,0.0025,54.1878
67.16,2.2361,3.2481,0.0036,54.634
67.78,2.2567,3.2741,0.0047,55.0718
68.4,2.2774,3.3002,0.0049,55.5112
69.02,2.298,3.3259,0.0023,55.9432
69.64,2.3187,3.3513,0.0035,56.3708
70.26,2.3394,3.3772,0.0052,56.8062
70.88,2.36,3.4023,0.003,57.228
71.5,2.3807,3.4279,0.0034,57.6592
72.12,2.4013,3.4532,0.0046,58.0849
72.74,2.4221,3.4789,0.0058,58.5158
73.36,2.4427,3.5042,0.0061,58.9421
73.98,2.4634,3.5297,0.0033,59.3705
74.6,2.4842,3.5556,0.0046,59.8072
75.22,2.5047,3.5799,0.0062,60.2155
75.84,2.5255,3.6056,0.0069,60.6479
76.46,2.5461,3.6304,0.0044,61.0651
77.08,2.5667,3.6552,0.0056,61.4828
77.7,2.5875,3.68,0.0071,61.8985
78.32,2.6081,3.7043,0.0041,62.3074
78.94,2.6288,3.7288,0.0046,62.7193
79.56,2.6494,3.7527,0.0057,63.1213
80.18,2.6702,3.7775,0.0075,63.5389
80.8,2.6907,3.8014,0.0056,63.9405
81.42,2.7115,3.8257,0.0053,64.3501
82.04,2.7322,3.85,0.0066,64.7583
82.66,2.7528,3.8737,0.0081,65.1578
83.28,2.7735,3.8979,0.0046,65.5642
83.9,2.7941,3.9217,0.0059,65.9651
84.52,2.8148,3.9456,0.0076,66.3669
85.14,2.8354,3.969,0.0092,66.7599
85.76,2.8562,3.9924,0.0056,67.1542
86.38,2.8768,4.0156,0.0068,67.5443
87,2.8973,4.0383,0.0078,67.9267
87.62,2.9181,4.0618,0.0091,68.3207
88.24,2.9387,4.0846,0.0062,68.7042
88.86,2.9594,4.1076,0.0069,69.0913
89.48,2.98,4.13,0.0084,69.4691
90.1,3.0007,4.153,0.0105,69.8547
90.72,3.0214,4.1758,0.0067,70.2392
91.34,3.042,4.198,0.0076,70.6121
91.96,3.0628,4.2213,0.0089,71.0038
92.58,3.0833,4.2433,0.0109,71.3745
93.2,3.104,4.266,0.0091,71.7557
93.82,3.1247,4.2885,0.0075,72.1344
94.44,3.1454,4.3111,0.0082,72.5143
95.06,3.166,4.3334,0.0097,72.8901
95.68,3.1867,4.3559,0.0111,73.2674
96.3,3.2075,4.3783,0.0073,73.6443
96.92,3.228,4.3996,0.0084,74.0036
97.54,3.2488,4.4217,0.0095,74.3755
98.16,3.2694,4.4433,0.011,74.7375
98.78,3.2901,4.465,0.0086,75.1026
99.4,3.3108,4.4865,0.0081,75.4657
100.02,3.3314,4.5078,0.0095,75.8229
100.64,3.3521,4.5294,0.0113,76.1862
101.26,3.3727,4.5503,0.0075,76.5386
101.88,3.3935,4.5721,0.0092,76.9054
102.5,3.4141,4.5933,0.0106,77.2607
103.12,3.4348,4.6145,0.0114,77.6174
103.74,3.4555,4.6361,0.0086,77.981
104.36,3.4761,4.6569,0.0094,78.3305
104.98,3.4968,4.6781,0.0105,78.687
105.6,3.5174,4.6987,0.0124,79.0342
106.22,3.5381,4.7197,0.0089,79.3874
106.84,3.5588,4.7401,0.01,79.7311
107.46,3.5795,4.7611,0.0115,80.0833
108.08,3.6001,4.7814,0.013,80.4259
108.7,3.6206,4.8014,0.0092,80.7612
109.32,3.6415,4.8225,0.0104,81.1159
109.94,3.662,4.8422,0.0121,81.4485
110.56,3.6828,4.8629,0.0137,81.7963
111.18,3.7034,4.8829,0.0097,82.1333
111.8,3.724,4.9032,0.011,82.4742
112.42,3.7447,4.9234,0.0128,82.8135
113.04,3.7653,4.9434,0.0145,83.1497
113.66,3.7861,4.9638,0.0112,83.4941
114.28,3.8066,4.9834,0.0126,83.823
114.9,3.8274,5.0036,0.0145,84.1627
115.52,3.848,5.0233,0.0107,84.4948
116.14,3.8687,5.0432,0.0123,84.829
116.76,3.8894,5.0628,0.0138,85.1586
117.38,3.9101,5.0826,0.0116,85.4913
118,3.9309,5.1025,0.0114,85.8264
118.62,3.9513,5.1212,0.0129,86.1412
119.24,3.9721,5.1411,0.0143,86.4764
119.86,3.9927,5.1606,0.0104,86.8038
120.48,4.0134,5.18,0.0119,87.1297
121.1,4.0341,5.1997,0.0133,87.461
121.72,4.0547,5.2186,0.0142,87.7791
122.34,4.0755,5.2381,0.0135,88.1077
122.96,4.096,5.2571,0.0117,88.4265
123.58,4.1168,5.2767,0.0128,88.757
124.2,4.1374,5.2954,0.0143,89.0708
124.82,4.1581,5.3145,0.0154,89.3914
125.44,4.1789,5.3338,0.0113,89.7166
126.06,4.1994,5.3522,0.0127,90.0262
126.68,4.2201,5.3711,0.0145,90.3437
127.3,4.2408,5.3896,0.0155,90.6553
127.92,4.2615,5.4084,0.0128,90.9717
128.54,4.2821,5.4264,0.0138,91.2744
129.16,4.3028,5.4449,0.0154,91.5849
129.78,4.3235,5.463,0.0157,91.8909
130.4,4.344,5.4807,0.0128,92.1878
131.02,4.3648,5.4994,0.0139,92.5021
131.64,4.3853,5.5172,0.0154,92.801
132.26,4.4061,5.5357,0.0151,93.1136
132.88,4.4267,5.5536,0.0126,93.4137
133.5,4.4473,5.5715,0.0139,93.715
134.12,4.4681,5.5896,0.0157,94.019
134.74,4.4886,5.6072,0.0135,94.3148
135.36,4.5094,5.6253,0.0136,94.6207
135.98,4.53,5.6428,0.0157,94.9147
136.6,4.5507,5.6605,0.0171,95.2117
137.22,4.5714,5.6781,0.0136,95.5084
137.84,4.5921,5.6957,0.015,95.8037
138.46,4.6127,5.713,0.0165,96.0951
139.08,4.6334,5.7303,0.0131,96.3863
139.7,4.6542,5.748,0.0142,96.6844
140.32,4.6747,5.7646,0.0156,96.9623
140.94,4.6955,5.7822,0.017,97.2583
141.56,4.7161,5.7992,0.0136,97.5454
142.18,4.7367,5.8162,0.0145,97.8313
142.8,4.7575,5.8335,0.0159,98.1216
143.42,4.7781,5.8502,0.0164,98.4029
144.04,4.7988,5.8673,0.0139,98.6905
144.66,4.8194,5.8838,0.0152,98.9687
145.28,4.8402,5.9011,0.0172,99.2583
145.9,4.8608,5.9174,0.0141,99.5336
146.52,4.8814,5.934,0.0151,99.8121
147.14,4.9022,5.9507,0.0166,100.094
147.76,4.9228,5.9668,0.0184,100.3636
148.38,4.9435,5.9833,0.0151,100.6421
149,4.9641,5.9995,0.0167,100.9149
149.62,4.9848,6.0159,0.0184,101.1898
150.217,5.0019,6.0221,0.0182,101.295
150.837,5.0016,5.9803,0.018,100.591
151.457,5.0013,5.9476,0.0178,100.0419
152.077,5.0013,5.9205,0.0178,99.5846
152.697,5.0012,5.8971,0.0178,99.1912
153.317,5.0012,5.8765,0.0178,98.8457
153.937,5.0012,5.858,0.0178,98.5341
154.557,5.0012,5.8413,0.0178,98.2524
155.177,5.0012,5.8257,0.0178,97.9906
155.797,5.0012,5.8119,0.0178,97.7579
156.417,5.0012,5.7987,0.0178,97.5368
157.014,5.004,5.7956,0.0194,97.484
157.634,5.0248,5.8502,0.0315,98.4034
158.254,5.0453,5.8977,0.0435,99.2016
158.874,5.0659,5.9402,0.0555,99.9173
159.494,5.0867,5.9793,0.0676,100.5746
160.114,5.1072,6.0151,0.0796,101.1761
160.734,5.1279,6.0479,0.0917,101.7289
161.354,5.1485,6.0784,0.1037,102.242
161.974,5.1693,6.1068,0.1158,102.719
162.594,5.1898,6.1325,0.1278,103.1521
163.214,5.2106,6.1571,0.1399,103.5659
163.834,5.2312,6.1799,0.1519,103.9486
164.454,5.2518,6.2011,0.1639,104.3054
165.074,5.2726,6.2218,0.1761,104.6537
165.694,5.2932,6.2407,0.1881,104.9721
166.314,5.3139,6.2594,0.2002,105.2859
166.934,5.3345,6.2768,0.2121,105.5785
167.554,5.3553,6.2941,0.2243,105.8698
168.174,5.3759,6.3108,0.2363,106.1511
168.794,5.3965,6.3266,0.2483,106.4169
169.414,5.4174,6.3434,0.2605,106.699
170.034,5.4379,6.3582,0.2725,106.9483
170.654,5.4586,6.3737,0.2845,107.2089
171.274,5.4793,6.3889,0.2966,107.4645
171.894,5.5,6.404,0.3087,107.7178
172.514,5.5206,6.4188,0.3207,107.9672
173.134,5.5413,6.4334,0.3327,108.2132
173.754,5.5621,6.4488,0.3449,108.4714
174.374,5.5825,6.4623,0.3568,108.6988
174.994,5.6034,6.4773,0.369,108.9513
175.614,5.624,6.4914,0.381,109.1878
176.234,5.6446,6.5057,0.393,109.428
176.854,5.6653,6.5199,0.4051,109.6675
177.474,5.686,6.5342,0.4172,109.9075
178.094,5.7067,6.5482,0.4292,110.1439
178.714,5.7272,6.5616,0.4412,110.3696
179.334,5.7481,6.5759,0.4534,110.61
179.954,5.7686,6.5894,0.4654,110.8368
180.574,5.7893,6.6029,0.4774,111.064
181.194,5.81,6.6169,0.4895,111.2983
181.814,5.8305,6.6301,0.5015,111.521
182.434,5.8513,6.6438,0.5136,111.7513
183.054,5.8719,6.6571,0.5256,111.9749
183.674,5.8926,6.6706,0.5377,112.203
184.294,5.9132,6.6839,0.5497,112.4255
184.914,5.9339,6.6971,0.5618,112.6487
185.534,5.9546,6.7105,0.5738,112.8731
186.154,5.9752,6.7235,0.5858,113.0922
186.774,5.9959,6.737,0.5979,113.319
187.394,6.0165,6.7499,0.61,113.5366
188.014,6.0373,6.763,0.6221,113.7559
188.634,6.0579,6.7754,0.6341,113.9654
189.254,6.0786,6.7886,0.6462,114.187
189.874,6.0993,6.8013,0.6582,114.4016
190.494,6.1199,6.8135,0.6702,114.606
191.114,6.1407,6.8266,0.6824,114.8267
191.734,6.1612,6.8387,0.6944,115.0301
192.354,6.1819,6.8512,0.7064,115.2404
192.974,6.2026,6.8635,0.7185,115.4465
193.594,6.2233,6.876,0.7305,115.6574
194.214,6.2439,6.888,0.7426,115.8595
194.834,6.2646,6.9001,0.7546,116.0633
195.454,6.2854,6.9125,0.7668,116.2705
196.074,6.3059,6.9238,0.7787,116.4614
196.694,6.3267,6.936,0.7908,116.6671
197.314,6.3473,6.9478,0.8029,116.8653
197.934,6.368,6.9593,0.8149,117.0589
198.554,6.3887,6.971,0.827,117.256
199.174,6.4093,6.9825,0.839,117.4491
199.794,6.43,6.9943,0.8511,117.6472
200.414,6.4506,7.0054,0.8631,117.8347
201.034,6.4714,7.0173,0.8753,118.0342
201.654,6.492,7.0284,0.8873,118.2213
202.274,6.5126,7.0396,0.8993,118.4089
202.894,6.5333,7.0511,0.9114,118.6021
203.514,6.5539,7.0617,0.9234,118.7815
204.134,6.5746,7.073,0.9355,118.9709
204.754,6.5952,7.0837,0.9475,119.1508
205.374,6.6159,7.0946,0.9596,119.3342
205.994,6.6365,7.1051,0.9716,119.5101
206.614,6.6572,7.1157,0.9836,119.6892
207.234,6.6779,7.1265,0.9957,119.8704
207.854,6.6985,7.1367,1.0077,120.0425
208.474,6.7193,7.1475,1.0198,120.2242
209.094,6.7399,7.1578,1.0319,120.3965
209.714,6.7606,7.1682,1.0439,120.572
210.334,6.7812,7.1777,1.0559,120.7319
210.954,6.8019,7.1881,1.068,120.9064
211.574,6.8227,7.1981,1.0801,121.0749
212.194,6.8432,7.2073,1.0921,121.2307
212.814,6.864,7.2177,1.1043,121.405
213.434,6.8846,7.2269,1.1162,121.5601
214.054,6.9053,7.2366,1.1283,121.7227
214.674,6.9259,7.2459,1.1404,121.8795
215.294,6.9466,7.2552,1.1524,122.0355
215.914,6.9673,7.2643,1.1645,122.1895
216.534,6.988,7.2733,1.1765,122.3404
217.154,7.0087,7.2824,1.1887,122.4938
217.774,7.0292,7.2909,1.2006,122.6362
218.394,7.05,7.3002,1.2128,122.7926
219.014,7.0707,7.309,1.2248,122.9407
219.634,7.0913,7.3174,1.2368,123.082
220.254,7.112,7.326,1.2489,123.2272
220.874,7.1327,7.3343,1.261,123.3662
221.494,7.1534,7.3425,1.273,123.5044
222.114,7.1739,7.3502,1.285,123.6332
222.734,7.1947,7.3583,1.2972,123.7691
223.354,7.2153,7.3655,1.3092,123.8904
223.974,7.2359,7.3727,1.3212,124.0117
224.594,7.2567,7.38,1.3333,124.1347
225.214,7.2772,7.3861,1.3452,124.2377
225.834,7.2979,7.3929,1.3573,124.3524
226.454,7.3186,7.3989,1.3694,124.4527
227.074,7.3393,7.4047,1.3815,124.5507
227.694,7.3599,7.4089,1.3935,124.6214
228.314,7.3805,7.4136,1.4055,124.6994
228.934,7.4013,7.4185,1.4176,124.7823
229.554,7.4218,7.4225,1.4296,124.8499
230.174,7.4426,7.4263,1.4417,124.9136
230.794,7.4632,7.4294,1.4537,124.9653
231.414,7.484,7.4322,1.4658,125.0134
232.034,7.5045,7.433,1.4778,125.0266
232.654,7.5253,7.4336,1.4899,125.0372
233.274,7.546,7.4327,1.502,125.0212
233.894,7.5665,7.4298,1.514,124.972
234.514,7.5874,7.4266,1.5262,124.9182
235.134,7.6079,7.4207,1.5381,124.8196
235.754,7.6286,7.4096,1.5502,124.6327
236.374,7.6493,7.3912,1.5623,124.3229
236.994,7.67,7.3642,1.5743,123.869
237.614,7.6906,7.3074,1.5864,122.9144
238.234,7.7113,7.1993,1.5984,121.0955
238.61,7.7244,4.6803,1.6061,78.7249
239.224,7.7442,4.2523,1.6176,71.5261
239.844,7.765,4.1461,1.6297,69.7385
240.464,7.7855,4.0829,1.6417,68.6757
241.084,7.8062,4.0525,1.6538,68.1643
241.704,7.827,4.0274,1.6659,67.7418
242.324,7.8476,4.0034,1.678,67.3381
242.944,7.8683,3.9828,1.69,66.9923
243.564,7.889,3.9268,1.7021,66.0501
244.184,7.9097,3.9027,1.7142,65.6447
244.804,7.9302,3.8926,1.7261,65.476
245.424,7.951,3.8889,1.7382,65.4135
246.044,7.9717,3.881,1.7503,65.2803
246.664,7.9922,3.8639,1.7623,64.9924
247.284,8.0131,3.8483,1.7744,64.73
247.904,8.0336,3.8282,1.7864,64.3926
248.524,8.0543,3.8104,1.7985,64.0928
249.144,8.075,3.7924,1.8106,63.7903
249.764,8.0957,3.77,1.8226,63.4136
250.384,8.1163,3.7289,1.8347,62.7222
251.004,8.1369,3.6675,1.8467,61.6896
251.624,8.1578,3.574,1.8588,60.1166
252.244,8.1783,3.4097,1.8708,57.3531
252.864,8.199,3.0415,1.8829,51.1597
253.484,8.2197,2.433,1.895,40.9238
254.104,8.2404,1.9058,1.907,32.057
254.724,8.261,1.7208,1.919,28.944
255.344,8.2816,1.6001,1.9311,26.9138
255.964,8.3023,1.3894,1.9432,23.3702
256.564,8.3222,0.4164,1.9548,7.0047
257.134,8.3413,0.3717,1.9659,6.2523