File: Yellow_Aramid.csv
1,Time,Displacement,Force,Tensile strain (Strain 1),Tensile stress
,(s),(mm),(kN),(%),(MPa)
"","0.0000","0.0000","0.0000","-0.0016","-0.0002"
"","0.1400","0.0020","0.0010","-0.0004","0.0473"
"","0.2800","0.0064","0.0038","-0.0005","0.1794"
"","0.4200","0.0111","0.0071","-0.0024","0.3362"
"","0.5600","0.0158","0.0112","-0.0007","0.5346"
"","0.7000","0.0206","0.0159","-0.0038","0.7582"
"","0.8400","0.0253","0.0213","-0.0013","1.0126"
"","0.9800","0.0300","0.0270","-0.0038","1.2835"
"","1.1200","0.0346","0.0332","-0.0009","1.5809"
"","1.2600","0.0394","0.0400","-0.0028","1.9041"
"","1.4000","0.0440","0.0471","0.0001","2.2414"
"","1.5400","0.0486","0.0537","0.0004","2.5594"
"","1.6800","0.0533","0.0600","0.0016","2.8585"
"","1.8200","0.0580","0.0651","0.0042","3.1005"
"","1.9600","0.0628","0.0699","0.0025","3.3288"
"","2.1000","0.0674","0.0744","0.0058","3.5436"
"","2.2400","0.0719","0.0783","0.0033","3.7278"
"","2.3800","0.0767","0.0828","0.0065","3.9408"
"","2.5200","0.0813","0.0866","0.0044","4.1237"
"","2.6600","0.0861","0.0906","0.0070","4.3141"
"","2.8000","0.0907","0.0945","0.0088","4.5016"
"","2.9400","0.0953","0.0988","0.0076","4.7048"
"","3.0800","0.1001","0.1028","0.0108","4.8952"
"","3.2200","0.1046","0.1070","0.0084","5.0949"
"","3.3600","0.1093","0.1114","0.0113","5.3027"
"","3.5000","0.1139","0.1160","0.0103","5.5218"
"","3.6400","0.1187","0.1207","0.0119","5.7483"
"","3.7800","0.1234","0.1255","0.0150","5.9746"
"","3.9200","0.1280","0.1299","0.0130","6.1841"
"","4.0600","0.1326","0.1346","0.0160","6.4118"
"","4.2000","0.1372","0.1393","0.0140","6.6349"
"","4.3400","0.1421","0.1444","0.0166","6.8771"
"","4.4800","0.1467","0.1492","0.0174","7.1059"
"","4.6200","0.1513","0.1540","0.0176","7.3354"
"","4.7600","0.1560","0.1591","0.0211","7.5763"
"","4.9000","0.1607","0.1640","0.0189","7.8116"
"","5.0400","0.1654","0.1691","0.0221","8.0523"
"","5.1800","0.1699","0.1737","0.0202","8.2721"
"","5.3200","0.1747","0.1789","0.0232","8.5190"
"","5.4600","0.1794","0.1839","0.0217","8.7562"
"","5.6000","0.1840","0.1889","0.0241","8.9942"
"","5.7400","0.1887","0.1938","0.0263","9.2287"
"","5.8800","0.1932","0.1984","0.0252","9.4483"
"","6.0200","0.1980","0.2035","0.0286","9.6921"
"","6.1600","0.2027","0.2084","0.0265","9.9225"
"","6.3000","0.2074","0.2133","0.0299","10.1550"
"","6.4400","0.2120","0.2180","0.0281","10.3824"
"","6.5800","0.2167","0.2228","0.0306","10.6108"
"","6.7200","0.2215","0.2278","0.0313","10.8492"
"","6.8600","0.2259","0.2322","0.0314","11.0589"
"","7.0000","0.2307","0.2370","0.0350","11.2862"
"","7.1400","0.2353","0.2416","0.0327","11.5069"
"","7.2800","0.2400","0.2464","0.0358","11.7332"
"","7.4200","0.2448","0.2510","0.0339","11.9504"
"","7.5600","0.2493","0.2553","0.0366","12.1594"
"","7.7000","0.2540","0.2597","0.0371","12.3668"
"","7.8400","0.2586","0.2642","0.0377","12.5809"
"","7.9800","0.2634","0.2688","0.0404","12.8012"
"","8.1200","0.2681","0.2732","0.0386","13.0094"
"","8.2600","0.2726","0.2773","0.0419","13.2055"
"","8.4000","0.2774","0.2818","0.0399","13.4192"
"","8.5400","0.2820","0.2860","0.0425","13.6185"
"","8.6800","0.2867","0.2903","0.0408","13.8219"
"","8.8200","0.2913","0.2944","0.0436","14.0200"
"","8.9600","0.2960","0.2987","0.0447","14.2225"
"","9.1000","0.3008","0.3030","0.0445","14.4270"
"","9.2400","0.3054","0.3068","0.0476","14.6087"
"","9.3800","0.3101","0.3110","0.0459","14.8101"
"","9.5200","0.3146","0.3147","0.0489","14.9839"
"","9.6600","0.3193","0.3188","0.0468","15.1825"
"","9.8000","0.3240","0.3229","0.0497","15.3758"
"","9.9400","0.3287","0.3270","0.0479","15.5702"
"","10.0800","0.3334","0.3310","0.0506","15.7614"
"","10.2200","0.3380","0.3349","0.0518","15.9490"
"","10.3600","0.3428","0.3391","0.0516","16.1499"
"","10.5000","0.3473","0.3429","0.0544","16.3269"
"","10.6400","0.3520","0.3469","0.0520","16.5214"
"","10.7800","0.3567","0.3513","0.0555","16.7287"
"","10.9200","0.3613","0.3561","0.0534","16.9551"
"","11.0600","0.3661","0.3608","0.0562","17.1824"
"","11.2000","0.3706","0.3649","0.0556","17.3766"
"","11.3400","0.3753","0.3693","0.0573","17.5837"
"","11.4800","0.3799","0.3733","0.0600","17.7770"
"","11.6200","0.3847","0.3775","0.0584","17.9750"
"","11.7600","0.3894","0.3816","0.0615","18.1725"
"","11.9000","0.3939","0.3852","0.0592","18.3447"
"","12.0400","0.3988","0.3893","0.0620","18.5392"
"","12.1800","0.4033","0.3930","0.0603","18.7142"
"","12.3200","0.4080","0.3969","0.0631","18.8990"
"","12.4600","0.4126","0.4005","0.0648","19.0721"
"","12.6000","0.4173","0.4044","0.0638","19.2576"
"","12.7400","0.4221","0.4084","0.0669","19.4480"
"","12.8800","0.4267","0.4121","0.0648","19.6226"
"","13.0200","0.4314","0.4159","0.0677","19.8032"
"","13.1600","0.4359","0.4195","0.0656","19.9756"
"","13.3000","0.4406","0.4233","0.0684","20.1586"
"","13.4400","0.4454","0.4274","0.0685","20.3533"
"","13.5800","0.4499","0.4309","0.0692","20.5180"
"","13.7200","0.4547","0.4348","0.0719","20.7063"
"","13.8600","0.4593","0.4385","0.0699","20.8823"
"","14.0000","0.4641","0.4423","0.0729","21.0643"
"","14.1400","0.4687","0.4460","0.0711","21.2375"
"","14.2800","0.4732","0.4495","0.0735","21.4069"
"","14.4200","0.4781","0.4535","0.0717","21.5946"
"","14.5600","0.4827","0.4571","0.0742","21.7660"
"","14.7000","0.4875","0.4609","0.0756","21.9469"
"","14.8400","0.4920","0.4641","0.0753","22.0978"
"","14.9800","0.4966","0.4676","0.0782","22.2645"
"","15.1200","0.5013","0.4712","0.0764","22.4385"
"","15.2600","0.5060","0.4748","0.0795","22.6086"
"","15.4000","0.5107","0.4782","0.0773","22.7720"
"","15.5400","0.5153","0.4814","0.0805","22.9261"
"","15.6800","0.5201","0.4853","0.0784","23.1097"
"","15.8200","0.5247","0.4885","0.0813","23.2641"
"","15.9600","0.5293","0.4919","0.0793","23.4233"
"","16.1000","0.5340","0.4954","0.0819","23.5915"
"","16.2400","0.5387","0.4989","0.0823","23.7555"
"","16.3800","0.5435","0.5027","0.0830","23.9359"
"","16.5200","0.5481","0.5059","0.0855","24.0912"
"","16.6600","0.5527","0.5093","0.0836","24.2542"
"","16.8000","0.5573","0.5126","0.0866","24.4083"
"","16.9400","0.5620","0.5161","0.0842","24.5763"
"","17.0800","0.5668","0.5196","0.0871","24.7423"
"","17.2200","0.5713","0.5227","0.0852","24.8922"
"","17.3600","0.5760","0.5263","0.0876","25.0612"
"","17.5000","0.5807","0.5295","0.0893","25.2147"
"","17.6400","0.5854","0.5329","0.0883","25.3755"
"","17.7800","0.5900","0.5361","0.0914","25.5290"
"","17.9200","0.5946","0.5392","0.0892","25.6777"
"","18.0600","0.5994","0.5429","0.0925","25.8521"
"","18.2000","0.6040","0.5461","0.0901","26.0035"
"","18.3400","0.6088","0.5494","0.0930","26.1620"
"","18.4800","0.6133","0.5525","0.0909","26.3115"
"","18.6200","0.6179","0.5557","0.0935","26.4614"
"","18.7600","0.6227","0.5592","0.0941","26.6297"
"","18.9000","0.6273","0.5624","0.0943","26.7802"
"","19.0400","0.6320","0.5656","0.0971","26.9341"
"","19.1800","0.6366","0.5687","0.0950","27.0795"
"","19.3200","0.6414","0.5722","0.0981","27.2461"
"","19.4600","0.6461","0.5753","0.0958","27.3935"
"","19.6000","0.6506","0.5781","0.0985","27.5307"
"","19.7400","0.6554","0.5816","0.0970","27.6930"
"","19.8800","0.6600","0.5847","0.0991","27.8416"
"","20.0200","0.6648","0.5879","0.1012","27.9976"
"","20.1600","0.6694","0.5910","0.0995","28.1419"
"","20.3000","0.6739","0.5938","0.1026","28.2783"
"","20.4400","0.6787","0.5970","0.1002","28.4305"
"","20.5800","0.6833","0.6001","0.1030","28.5757"
"","20.7200","0.6881","0.6035","0.1009","28.7372"
"","20.8600","0.6926","0.6063","0.1035","28.8727"
"","21.0000","0.6974","0.6095","0.1037","29.0234"
"","21.1400","0.7021","0.6127","0.1041","29.1758"
"","21.2800","0.7067","0.6156","0.1068","29.3127"
"","21.4200","0.7114","0.6188","0.1048","29.4653"
"","21.5600","0.7159","0.6216","0.1076","29.6004"
"","21.7000","0.7207","0.6250","0.1054","29.7624"
"","21.8400","0.7254","0.6280","0.1082","29.9069"
"","21.9800","0.7301","0.6313","0.1065","30.0602"
"","22.1200","0.7347","0.6342","0.1088","30.2000"
"","22.2600","0.7393","0.6371","0.1107","30.3375"
"","22.4000","0.7441","0.6403","0.1092","30.4926"
"","22.5400","0.7487","0.6434","0.1121","30.6360"
"","22.6800","0.7534","0.6463","0.1098","30.7776"
"","22.8200","0.7580","0.6494","0.1125","30.9233"
"","22.9600","0.7627","0.6524","0.1106","31.0669"
"","23.1000","0.7674","0.6557","0.1132","31.2215"
"","23.2400","0.7719","0.6583","0.1143","31.3498"
"","23.3800","0.7767","0.6616","0.1135","31.5027"
"","23.5200","0.7813","0.6646","0.1168","31.6456"
"","23.6600","0.7861","0.6677","0.1145","31.7949"
"","23.8000","0.7908","0.6709","0.1174","31.9470"
"","23.9400","0.7952","0.6734","0.1151","32.0683"
"","24.0800","0.8000","0.6768","0.1179","32.2302"
"","24.2200","0.8046","0.6797","0.1160","32.3676"
"","24.3600","0.8094","0.6831","0.1185","32.5291"
"","24.5000","0.8139","0.6860","0.1199","32.6687"
"","24.6400","0.8187","0.6893","0.1191","32.8241"
"","24.7800","0.8234","0.6926","0.1223","32.9800"
"","24.9200","0.8280","0.6954","0.1202","33.1133"
"","25.0600","0.8327","0.6986","0.1230","33.2684"
"","25.2000","0.8373","0.7016","0.1211","33.4095"
"","25.3400","0.8420","0.7048","0.1236","33.5643"
"","25.4800","0.8468","0.7081","0.1217","33.7201"
"","25.6200","0.8513","0.7109","0.1243","33.8540"
"","25.7600","0.8560","0.7140","0.1249","33.9986"
"","25.9000","0.8606","0.7170","0.1252","34.1439"
"","26.0400","0.8654","0.7204","0.1281","34.3037"
"","26.1800","0.8700","0.7235","0.1258","34.4510"
"","26.3200","0.8746","0.7263","0.1292","34.5881"
"","26.4600","0.8794","0.7296","0.1271","34.7450"
"","26.6000","0.8840","0.7325","0.1296","34.8808"
"","26.7400","0.8887","0.7357","0.1277","35.0311"
"","26.8800","0.8932","0.7384","0.1303","35.1636"
"","27.0200","0.8980","0.7416","0.1291","35.3132"
"","27.1600","0.9027","0.7447","0.1311","35.4621"
"","27.3000","0.9074","0.7477","0.1331","35.6056"
"","27.4400","0.9121","0.7509","0.1320","35.7549"
"","27.5800","0.9166","0.7536","0.1350","35.8875"
"","27.7200","0.9214","0.7569","0.1328","36.0436"
"","27.8600","0.9260","0.7601","0.1361","36.1937"
"","28.0000","0.9307","0.7633","0.1341","36.3493"
"","28.1400","0.9353","0.7665","0.1369","36.4996"
"","28.2800","0.9400","0.7696","0.1350","36.6491"
"","28.4200","0.9448","0.7732","0.1376","36.8169"
"","28.5600","0.9493","0.7761","0.1357","36.9585"
"","28.7000","0.9540","0.7795","0.1386","37.1205"
"","28.8400","0.9586","0.7827","0.1391","37.2703"
"","28.9800","0.9634","0.7862","0.1398","37.4383"
"","29.1200","0.9682","0.7896","0.1423","37.6015"
"","29.2600","0.9727","0.7927","0.1407","37.7465"
"","29.4000","0.9773","0.7960","0.1440","37.9064"
"","29.5400","0.9819","0.7993","0.1419","38.0599"
"","29.6800","0.9867","0.8028","0.1450","38.2306"
"","29.8200","0.9914","0.8061","0.1427","38.3852"
"","29.9600","0.9959","0.8092","0.1457","38.5343"
"","30.1000","1.0008","0.8129","0.1439","38.7080"
"","30.2400","1.0053","0.8161","0.1466","38.8599"
"","30.3800","1.0101","0.8194","0.1468","39.0184"
"","30.5200","1.0146","0.8226","0.1474","39.1693"
"","30.6600","1.0193","0.8259","0.1502","39.3276"
"","30.8000","1.0241","0.8295","0.1484","39.5021"
"","30.9400","1.0287","0.8326","0.1513","39.6497"
"","31.0800","1.0334","0.8361","0.1494","39.8130"
"","31.2200","1.0379","0.8391","0.1523","39.9577"
"","31.3600","1.0427","0.8428","0.1505","40.1334"
"","31.5000","1.0474","0.8462","0.1532","40.2934"
"","31.6400","1.0520","0.8494","0.1525","40.4486"
"","31.7800","1.0567","0.8528","0.1543","40.6110"
"","31.9200","1.0614","0.8562","0.1565","40.7703"
"","32.0600","1.0661","0.8595","0.1553","40.9282"
"","32.2000","1.0707","0.8629","0.1583","41.0904"
"","32.3400","1.0753","0.8660","0.1561","41.2405"
"","32.4800","1.0800","0.8695","0.1593","41.4055"
"","32.6200","1.0847","0.8729","0.1574","41.5656"
"","32.7600","1.0895","0.8763","0.1598","41.7283"
"","32.9000","1.0940","0.8793","0.1585","41.8727"
"","33.0400","1.0986","0.8825","0.1610","42.0237"
"","33.1800","1.1033","0.8858","0.1624","42.1798"
"","33.3200","1.1080","0.8891","0.1622","42.3385"
"","33.4600","1.1127","0.8924","0.1651","42.4938"
"","33.6000","1.1172","0.8954","0.1629","42.6389"
"","33.7400","1.1221","0.8990","0.1664","42.8099"
"","33.8800","1.1267","0.9021","0.1642","42.9561"
"","34.0200","1.1314","0.9054","0.1672","43.1137"
"","34.1600","1.1359","0.9085","0.1651","43.2609"
"","34.3000","1.1407","0.9118","0.1682","43.4195"
"","34.4400","1.1455","0.9153","0.1666","43.5864"
"","34.5800","1.1501","0.9183","0.1691","43.7280"
"","34.7200","1.1547","0.9215","0.1701","43.8802"
"","34.8600","1.1592","0.9246","0.1700","44.0279"
"","35.0000","1.1640","0.9278","0.1729","44.1828"
"","35.1400","1.1687","0.9312","0.1712","44.3447"
"","35.2800","1.1733","0.9342","0.1744","44.4857"
"","35.4200","1.1781","0.9378","0.1722","44.6560"
"","35.5600","1.1827","0.9409","0.1753","44.8064"
"","35.7000","1.1874","0.9442","0.1735","44.9630"
"","35.8400","1.1920","0.9473","0.1763","45.1108"
"","35.9800","1.1966","0.9504","0.1746","45.2570"
"","36.1200","1.2014","0.9539","0.1773","45.4221"
"","36.2600","1.2060","0.9568","0.1760","45.5628"
"","36.4000","1.2108","0.9602","0.1785","45.7245"
"","36.5400","1.2153","0.9630","0.1803","45.8587"
"","36.6800","1.2199","0.9661","0.1795","46.0070"
"","36.8200","1.2247","0.9696","0.1826","46.1699"
"","36.9600","1.2294","0.9726","0.1805","46.3151"
"","37.1000","1.2341","0.9760","0.1836","46.4762"
"","37.2400","1.2386","0.9789","0.1814","46.6159"
"","37.3800","1.2434","0.9822","0.1843","46.7728"
"","37.5200","1.2481","0.9855","0.1824","46.9270"
"","37.6600","1.2526","0.9885","0.1851","47.0712"
"","37.8000","1.2573","0.9917","0.1858","47.2247"
"","37.9400","1.2620","0.9947","0.1861","47.3683"
"","38.0800","1.2668","0.9981","0.1890","47.5295"
"","38.2200","1.2714","1.0012","0.1871","47.6779"
"","38.3600","1.2760","1.0041","0.1903","47.8122"
"","38.5000","1.2806","1.0072","0.1881","47.9604"
"","38.6400","1.2853","1.0103","0.1911","48.1081"
"","38.7800","1.2901","1.0135","0.1895","48.2607"
"","38.9200","1.2946","1.0165","0.1920","48.4025"
"","39.0600","1.2993","1.0197","0.1905","48.5559"
"","39.2000","1.3040","1.0228","0.1932","48.7065"
"","39.3400","1.3087","1.0261","0.1946","48.8610"
"","39.4800","1.3134","1.0292","0.1942","49.0097"
"","39.6200","1.3179","1.0321","0.1972","49.1468"
"","39.7600","1.3228","1.0357","0.1950","49.3196"
"","39.9000","1.3274","1.0387","0.1982","49.4636"
"","40.0400","1.3321","1.0422","0.1960","49.6289"
"","40.1800","1.3366","1.0451","0.1988","49.7678"
"","40.3200","1.3413","1.0484","0.1973","49.9231"
"","40.4600","1.3461","1.0518","0.1999","50.0878"
"","40.6000","1.3506","1.0550","0.2004","50.2375"
"","40.7400","1.3554","1.0584","0.2011","50.3977"
"","40.8800","1.3599","1.0615","0.2035","50.5456"
"","41.0200","1.3648","1.0651","0.2025","50.7170"
"","41.1600","1.3694","1.0682","0.2057","50.8679"
"","41.3000","1.3739","1.0713","0.2036","51.0136"
"","41.4400","1.3787","1.0748","0.2067","51.1824"
"","41.5800","1.3833","1.0781","0.2047","51.3369"
"","41.7200","1.3881","1.0816","0.2078","51.5051"
"","41.8600","1.3928","1.0848","0.2061","51.6574"
"","42.0000","1.3972","1.0879","0.2089","51.8032"
"","42.1400","1.4020","1.0914","0.2074","51.9727"
"","42.2800","1.4066","1.0947","0.2103","52.1279"
"","42.4200","1.4115","1.0983","0.2091","52.2999"
"","42.5600","1.4159","1.1013","0.2115","52.4450"
"","42.7000","1.4207","1.1049","0.2132","52.6131"
"","42.8400","1.4254","1.1082","0.2129","52.7704"
"","42.9800","1.4300","1.1113","0.2159","52.9213"
"","43.1200","1.4346","1.1146","0.2141","53.0782"
"","43.2600","1.4392","1.1179","0.2170","53.2350"
"","43.4000","1.4441","1.1214","0.2151","53.3995"
"","43.5400","1.4487","1.1248","0.2180","53.5620"
"","43.6800","1.4534","1.1280","0.2162","53.7133"
"","43.8200","1.4580","1.1312","0.2188","53.8669"
"","43.9600","1.4626","1.1343","0.2205","54.0145"
"","44.1000","1.4674","1.1379","0.2201","54.1861"
"","44.2400","1.4720","1.1412","0.2230","54.3447"
"","44.3800","1.4766","1.1445","0.2211","54.5005"
"","44.5200","1.4813","1.1480","0.2243","54.6645"
"","44.6600","1.4860","1.1512","0.2226","54.8192"
"","44.8000","1.4908","1.1549","0.2257","54.9941"
"","44.9400","1.4952","1.1579","0.2241","55.1373"
"","45.0800","1.5001","1.1615","0.2271","55.3112"
"","45.2200","1.5046","1.1647","0.2254","55.4617"
"","45.3600","1.5095","1.1683","0.2287","55.6358"
"","45.5000","1.5141","1.1716","0.2267","55.7918"
"","45.6400","1.5186","1.1748","0.2295","55.9452"
"","45.7800","1.5234","1.1783","0.2306","56.1116"
"","45.9200","1.5280","1.1817","0.2306","56.2698"
"","46.0600","1.5327","1.1852","0.2337","56.4369"
"","46.2000","1.5373","1.1884","0.2319","56.5915"
"","46.3400","1.5420","1.1917","0.2350","56.7486"
"","46.4800","1.5468","1.1953","0.2329","56.9199"
"","46.6200","1.5513","1.1984","0.2360","57.0688"
"","46.7600","1.5560","1.2019","0.2344","57.2331"
"","46.9000","1.5606","1.2052","0.2371","57.3886"
"","47.0400","1.5654","1.2087","0.2370","57.5577"
"","47.1800","1.5701","1.2121","0.2383","57.7211"
"","47.3200","1.5747","1.2153","0.2405","57.8737"
"","47.4600","1.5793","1.2188","0.2394","58.0397"
"","47.6000","1.5839","1.2220","0.2425","58.1882"
"","47.7400","1.5887","1.2258","0.2408","58.3692"
"","47.8800","1.5934","1.2290","0.2438","58.5241"
"","48.0200","1.5980","1.2322","0.2420","58.6785"
"","48.1600","1.6027","1.2359","0.2449","58.8539"
"","48.3000","1.6073","1.2390","0.2431","59.0023"
"","48.4400","1.6120","1.2427","0.2460","59.1761"
"","48.5800","1.6165","1.2458","0.2466","59.3217"
"","48.7200","1.6213","1.2492","0.2473","59.4875"
"","48.8600","1.6261","1.2529","0.2503","59.6632"
"","49.0000","1.6308","1.2562","0.2484","59.8194"
"","49.1400","1.6354","1.2595","0.2516","59.9771"
"","49.2800","1.6399","1.2626","0.2495","60.1245"
"","49.4200","1.6447","1.2663","0.2528","60.2989"
"","49.5600","1.6493","1.2697","0.2508","60.4605"
"","49.7000","1.6541","1.2732","0.2540","60.6288"
"","49.8400","1.6587","1.2766","0.2524","60.7924"
"","49.9800","1.6633","1.2799","0.2555","60.9462"
"","50.1200","1.6681","1.2835","0.2541","61.1198"
"","50.2600","1.6726","1.2866","0.2566","61.2665"
"","50.4000","1.6773","1.2901","0.2580","61.4329"
"","50.5400","1.6820","1.2935","0.2579","61.5945"
"","50.6800","1.6867","1.2969","0.2608","61.7593"
"","50.8200","1.6915","1.3005","0.2591","61.9288"
"","50.9600","1.6960","1.3037","0.2621","62.0808"
"","51.1000","1.7006","1.3071","0.2602","62.2452"
"","51.2400","1.7053","1.3106","0.2635","62.4080"
"","51.3800","1.7100","1.3142","0.2616","62.5787"
"","51.5200","1.7147","1.3177","0.2646","62.7454"
"","51.6600","1.7193","1.3209","0.2632","62.8988"
"","51.8000","1.7241","1.3246","0.2659","63.0760"
"","51.9400","1.7286","1.3278","0.2655","63.2284"
"","52.0800","1.7334","1.3314","0.2676","63.3982"
"","52.2200","1.7379","1.3348","0.2689","63.5609"
"","52.3600","1.7426","1.3382","0.2687","63.7226"
"","52.5000","1.7474","1.3419","0.2719","63.8985"
"","52.6400","1.7520","1.3453","0.2703","64.0644"
"","52.7800","1.7567","1.3489","0.2737","64.2327"
"","52.9200","1.7612","1.3520","0.2717","64.3818"
"","53.0600","1.7660","1.3557","0.2752","64.5573"
"","53.2000","1.7707","1.3593","0.2733","64.7269"
"","53.3400","1.7753","1.3626","0.2765","64.8862"
"","53.4800","1.7800","1.3663","0.2749","65.0610"
"","53.6200","1.7847","1.3696","0.2779","65.2206"
"","53.7600","1.7894","1.3734","0.2763","65.3985"
"","53.9000","1.7940","1.3768","0.2790","65.5613"
"","54.0400","1.7986","1.3802","0.2797","65.7248"
"","54.1800","1.8033","1.3837","0.2803","65.8899"
"","54.3200","1.8080","1.3871","0.2832","66.0534"
"","54.4600","1.8128","1.3907","0.2815","66.2253"
"","54.6000","1.8173","1.3939","0.2847","66.3773"
"","54.7400","1.8220","1.3972","0.2828","66.5351"
"","54.8800","1.8266","1.4008","0.2857","66.7037"
"","55.0200","1.8313","1.4043","0.2841","66.8708"
"","55.1600","1.8360","1.4078","0.2867","67.0365"
"","55.3000","1.8406","1.4110","0.2869","67.1911"
"","55.4400","1.8454","1.4147","0.2880","67.3664"
"","55.5800","1.8500","1.4179","0.2907","67.5193"
"","55.7200","1.8547","1.4213","0.2896","67.6810"
"","55.8600","1.8593","1.4246","0.2926","67.8400"
"","56.0000","1.8640","1.4282","0.2906","68.0103"
"","56.1400","1.8688","1.4317","0.2939","68.1786"
"","56.2800","1.8734","1.4351","0.2921","68.3370"
"","56.4200","1.8780","1.4385","0.2950","68.4992"
"","56.5600","1.8826","1.4417","0.2933","68.6538"
"","56.7000","1.8873","1.4453","0.2963","68.8244"
"","56.8400","1.8921","1.4490","0.2957","68.9993"
"","56.9800","1.8966","1.4522","0.2977","69.1509"
"","57.1200","1.9014","1.4558","0.3001","69.3232"
"","57.2600","1.9060","1.4592","0.2989","69.4873"
"","57.4000","1.9107","1.4628","0.3022","69.6555"
"","57.5400","1.9153","1.4662","0.3005","69.8195"
"","57.6800","1.9199","1.4696","0.3037","69.9807"
"","57.8200","1.9248","1.4734","0.3020","70.1619"
"","57.9600","1.9293","1.4767","0.3048","70.3178"
"","58.1000","1.9341","1.4804","0.3033","70.4952"
"","58.2400","1.9386","1.4837","0.3063","70.6533"
"","58.3800","1.9433","1.4872","0.3048","70.8201"
"","58.5200","1.9480","1.4909","0.3076","70.9967"
"","58.6600","1.9527","1.4943","0.3069","71.1557"
"","58.8000","1.9574","1.4980","0.3090","71.3315"
"","58.9400","1.9620","1.5013","0.3108","71.4917"
"","59.0800","1.9667","1.5050","0.3106","71.6686"
"","59.2200","1.9714","1.5086","0.3137","71.8393"
"","59.3600","1.9760","1.5118","0.3122","71.9921"
"","59.5000","1.9807","1.5156","0.3152","72.1693"
"","59.6400","1.9853","1.5191","0.3135","72.3369"
"","59.7800","1.9901","1.5227","0.3168","72.5117"
"","59.9200","1.9948","1.5262","0.3149","72.6749"
"","60.0600","1.9993","1.5294","0.3180","72.8304"
"","60.2000","2.0039","1.5329","0.3165","72.9961"
"","60.3400","2.0086","1.5365","0.3191","73.1661"
"","60.4800","2.0134","1.5402","0.3178","73.3444"
"","60.6200","2.0179","1.5435","0.3206","73.4979"
"","60.7600","2.0227","1.5472","0.3210","73.6784"
"","60.9000","2.0274","1.5508","0.3221","73.8465"
"","61.0400","2.0320","1.5542","0.3249","74.0090"
"","61.1800","2.0367","1.5577","0.3235","74.1778"
"","61.3200","2.0412","1.5610","0.3268","74.3316"
"","61.4600","2.0461","1.5648","0.3249","74.5160"
"","61.6000","2.0507","1.5683","0.3281","74.6812"
"","61.7400","2.0554","1.5718","0.3262","74.8501"
"","61.8800","2.0600","1.5751","0.3294","75.0063"
"","62.0200","2.0646","1.5786","0.3279","75.1712"
"","62.1600","2.0694","1.5825","0.3310","75.3577"
"","62.3000","2.0740","1.5858","0.3297","75.5155"
"","62.4400","2.0787","1.5894","0.3327","75.6875"
"","62.5800","2.0833","1.5928","0.3312","75.8498"
"","62.7200","2.0881","1.5965","0.3341","76.0253"
"","62.8600","2.0927","1.6001","0.3334","76.1940"
"","63.0000","2.0972","1.6033","0.3358","76.3457"
"","63.1400","2.1020","1.6071","0.3370","76.5310"
"","63.2800","2.1067","1.6106","0.3373","76.6952"
"","63.4200","2.1114","1.6143","0.3397","76.8713"
"","63.5600","2.1161","1.6179","0.3387","77.0412"
"","63.7000","2.1206","1.6209","0.3418","77.1866"
"","63.8400","2.1254","1.6247","0.3400","77.3648"
"","63.9800","2.1300","1.6281","0.3436","77.5281"
"","64.1200","2.1348","1.6318","0.3416","77.7035"
"","64.2600","2.1393","1.6351","0.3447","77.8610"
"","64.4000","2.1440","1.6389","0.3431","78.0410"
"","64.5400","2.1488","1.6424","0.3458","78.2108"
"","64.6800","2.1533","1.6459","0.3444","78.3740"
"","64.8200","2.1580","1.6494","0.3474","78.5447"
"","64.9600","2.1626","1.6529","0.3467","78.7088"
"","65.1000","2.1674","1.6567","0.3489","78.8910"
"","65.2400","2.1721","1.6601","0.3504","79.0531"
"","65.3800","2.1768","1.6635","0.3502","79.2162"
"","65.5200","2.1813","1.6668","0.3533","79.3722"
"","65.6600","2.1860","1.6705","0.3516","79.5470"
"","65.8000","2.1907","1.6741","0.3549","79.7179"
"","65.9400","2.1954","1.6776","0.3528","79.8848"
"","66.0800","2.2000","1.6809","0.3560","80.0444"
"","66.2200","2.2047","1.6844","0.3544","80.2104"
"","66.3600","2.2093","1.6878","0.3574","80.3704"
"","66.5000","2.2141","1.6915","0.3560","80.5477"
"","66.6400","2.2186","1.6946","0.3586","80.6971"
"","66.7800","2.2233","1.6983","0.3591","80.8700"
"","66.9200","2.2280","1.7017","0.3603","81.0324"
"","67.0600","2.2328","1.7053","0.3626","81.2065"
"","67.2000","2.2374","1.7087","0.3617","81.3657"
"","67.3400","2.2419","1.7119","0.3648","81.5214"
"","67.4800","2.2467","1.7156","0.3633","81.6968"
"","67.6200","2.2513","1.7188","0.3666","81.8495"
"","67.7600","2.2561","1.7226","0.3649","82.0273"
"","67.9000","2.2607","1.7257","0.3680","82.1751"
"","68.0400","2.2654","1.7291","0.3663","82.3398"
"","68.1800","2.2701","1.7326","0.3696","82.5071"
"","68.3200","2.2747","1.7359","0.3677","82.6629"
"","68.4600","2.2793","1.7393","0.3704","82.8262"
"","68.6000","2.2839","1.7426","0.3688","82.9834"
"","68.7400","2.2887","1.7463","0.3716","83.1595"
"","68.8800","2.2935","1.7499","0.3722","83.3300"
"","69.0200","2.2980","1.7530","0.3730","83.4770"
"","69.1600","2.3027","1.7565","0.3757","83.6447"
"","69.3000","2.3073","1.7599","0.3747","83.8035"
"","69.4400","2.3121","1.7635","0.3780","83.9771"
"","69.5800","2.3167","1.7671","0.3760","84.1494"
"","69.7200","2.3213","1.7704","0.3792","84.3055"
"","69.8600","2.3261","1.7742","0.3773","84.4869"
"","70.0000","2.3306","1.7775","0.3805","84.6432"
"","70.1400","2.3354","1.7812","0.3791","84.8197"
"","70.2800","2.3399","1.7845","0.3817","84.9774"
"","70.4200","2.3447","1.7882","0.3804","85.1512"
"","70.5600","2.3494","1.7918","0.3833","85.3258"
"","70.7000","2.3541","1.7954","0.3835","85.4977"
"","70.8400","2.3587","1.7990","0.3846","85.6654"
"","70.9800","2.3632","1.8023","0.3872","85.8233"
"","71.1200","2.3680","1.8061","0.3862","86.0059"
"","71.2600","2.3727","1.8097","0.3894","86.1769"
"","71.4000","2.3774","1.8134","0.3879","86.3516"
"","71.5400","2.3820","1.8170","0.3910","86.5244"
"","71.6800","2.3867","1.8205","0.3892","86.6919"
"","71.8200","2.3915","1.8243","0.3925","86.8714"
"","71.9600","2.3960","1.8278","0.3906","87.0359"
"","72.1000","2.4007","1.8313","0.3936","87.2058"
"","72.2400","2.4053","1.8348","0.3920","87.3725"
"","72.3800","2.4100","1.8385","0.3951","87.5477"
"","72.5200","2.4148","1.8424","0.3948","87.7325"
"","72.6600","2.4193","1.8456","0.3964","87.8870"
"","72.8000","2.4240","1.8493","0.3987","88.0619"
"","72.9400","2.4286","1.8528","0.3978","88.2269"
"","73.0800","2.4334","1.8567","0.4011","88.4156"
"","73.2200","2.4381","1.8603","0.3994","88.5854"
"","73.3600","2.4426","1.8636","0.4025","88.7442"
"","73.5000","2.4474","1.8677","0.4008","88.9365"
"","73.6400","2.4520","1.8712","0.4041","89.1045"
"","73.7800","2.4567","1.8749","0.4022","89.2796"
"","73.9200","2.4613","1.8783","0.4055","89.4437"
"","74.0600","2.4660","1.8820","0.4041","89.6188"
"","74.2000","2.4708","1.8860","0.4072","89.8098"
"","74.3400","2.4754","1.8895","0.4058","89.9786"
"","74.4800","2.4801","1.8932","0.4085","90.1517"
"","74.6200","2.4846","1.8966","0.4095","90.3164"
"","74.7600","2.4893","1.9003","0.4100","90.4917"
"","74.9000","2.4941","1.9040","0.4129","90.6686"
"","75.0400","2.4987","1.9078","0.4117","90.8471"
"","75.1800","2.5033","1.9113","0.4149","91.0130"
"","75.3200","2.5080","1.9150","0.4130","91.1886"
"","75.4600","2.5127","1.9188","0.4164","91.3702"
"","75.6000","2.5173","1.9223","0.4145","91.5375"
"","75.7400","2.5219","1.9259","0.4177","91.7103"
"","75.8800","2.5267","1.9297","0.4163","91.8926"
"","76.0200","2.5314","1.9333","0.4192","92.0627"
"","76.1600","2.5361","1.9372","0.4180","92.2455"
"","76.3000","2.5406","1.9405","0.4209","92.4059"
"","76.4400","2.5453","1.9442","0.4197","92.5828"
"","76.5800","2.5499","1.9478","0.4223","92.7548"
"","76.7200","2.5547","1.9517","0.4229","92.9370"
"","76.8600","2.5594","1.9555","0.4240","93.1194"
"","77.0000","2.5639","1.9589","0.4262","93.2808"
"","77.1400","2.5688","1.9629","0.4256","93.4736"
"","77.2800","2.5734","1.9665","0.4290","93.6411"
"","77.4200","2.5780","1.9701","0.4269","93.8148"
"","77.5600","2.5826","1.9737","0.4303","93.9858"
"","77.7000","2.5873","1.9774","0.4285","94.1620"
"","77.8400","2.5921","1.9813","0.4316","94.3482"
"","77.9800","2.5967","1.9848","0.4303","94.5137"
"","78.1200","2.6014","1.9883","0.4331","94.6821"
"","78.2600","2.6059","1.9920","0.4318","94.8578"
"","78.4000","2.6106","1.9956","0.4347","95.0305"
"","78.5400","2.6154","1.9995","0.4342","95.2145"
"","78.6800","2.6200","2.0027","0.4363","95.3656"
"","78.8200","2.6247","2.0065","0.4375","95.5486"
"","78.9600","2.6293","2.0100","0.4376","95.7160"
"","79.1000","2.6341","2.0137","0.4403","95.8893"
"","79.2400","2.6387","2.0173","0.4394","96.0614"
"","79.3800","2.6432","2.0206","0.4425","96.2200"
"","79.5200","2.6481","2.0246","0.4408","96.4076"
"","79.6600","2.6527","2.0279","0.4440","96.5691"
"","79.8000","2.6575","2.0318","0.4425","96.7548"
"","79.9400","2.6620","2.0351","0.4456","96.9100"
"","80.0800","2.6666","2.0387","0.4439","97.0823"
"","80.2200","2.6714","2.0426","0.4471","97.2665"
"","80.3600","2.6760","2.0461","0.4458","97.4332"
"","80.5000","2.6807","2.0498","0.4489","97.6092"
"","80.6400","2.6853","2.0533","0.4474","97.7785"
"","80.7800","2.6900","2.0570","0.4506","97.9533"
"","80.9200","2.6947","2.0606","0.4488","98.1263"
"","81.0600","2.6993","2.0641","0.4519","98.2902"
"","81.2000","2.7040","2.0678","0.4518","98.4651"
"","81.3400","2.7087","2.0713","0.4534","98.6343"
"","81.4800","2.7135","2.0751","0.4548","98.8150"
"","81.6200","2.7181","2.0784","0.4550","98.9719"
"","81.7600","2.7226","2.0819","0.4572","99.1373"
"","81.9000","2.7273","2.0855","0.4564","99.3096"
"","82.0400","2.7319","2.0890","0.4595","99.4753"
"","82.1800","2.7367","2.0928","0.4582","99.6558"
"","82.3200","2.7413","2.0961","0.4614","99.8138"
"","82.4600","2.7460","2.0997","0.4596","99.9867"
"","82.6000","2.7507","2.1034","0.4631","100.1609"
"","82.7400","2.7554","2.1069","0.4616","100.3292"
"","82.8800","2.7600","2.1103","0.4647","100.4916"
"","83.0200","2.7646","2.1138","0.4632","100.6557"
"","83.1600","2.7694","2.1177","0.4665","100.8433"
"","83.3000","2.7740","2.1210","0.4647","101.0018"
"","83.4400","2.7788","2.1249","0.4679","101.1854"
"","83.5800","2.7833","2.1283","0.4664","101.3481"
"","83.7200","2.7879","2.1318","0.4695","101.5130"
"","83.8600","2.7927","2.1356","0.4680","101.6931"
"","84.0000","2.7973","2.1391","0.4710","101.8604"
"","84.1400","2.8020","2.1427","0.4701","102.0351"
"","84.2800","2.8066","2.1462","0.4723","102.2007"
"","84.4200","2.8114","2.1500","0.4734","102.3827"
"","84.5600","2.8161","2.1536","0.4741","102.5513"
"","84.7000","2.8205","2.1568","0.4764","102.7032"
"","84.8400","2.8253","2.1607","0.4756","102.8919"
"","84.9800","2.8300","2.1643","0.4789","103.0600"
"","85.1200","2.8348","2.1681","0.4771","103.2411"
"","85.2600","2.8394","2.1716","0.4803","103.4117"
"","85.4000","2.8439","2.1749","0.4788","103.5649"
"","85.5400","2.8487","2.1787","0.4818","103.7455"
"","85.6800","2.8533","2.1820","0.4804","103.9066"
"","85.8200","2.8581","2.1861","0.4837","104.0980"
"","85.9600","2.8626","2.1893","0.4821","104.2544"
"","86.1000","2.8673","2.1931","0.4851","104.4343"
"","86.2400","2.8720","2.1968","0.4836","104.6089"
"","86.3800","2.8767","2.2003","0.4866","104.7771"
"","86.5200","2.8814","2.2041","0.4852","104.9561"
"","86.6600","2.8859","2.2075","0.4882","105.1172"
"","86.8000","2.8908","2.2113","0.4870","105.3006"
"","86.9400","2.8954","2.2149","0.4900","105.4713"
"","87.0800","2.9001","2.2186","0.4896","105.6475"
"","87.2200","2.9047","2.2219","0.4914","105.8027"
"","87.3600","2.9093","2.2254","0.4931","105.9705"
"","87.5000","2.9141","2.2291","0.4932","106.1485"
"","87.6400","2.9187","2.2328","0.4961","106.3245"
"","87.7800","2.9233","2.2363","0.4946","106.4899"
"","87.9200","2.9280","2.2399","0.4980","106.6614"
"","88.0600","2.9327","2.2434","0.4961","106.8272"
"","88.2000","2.9374","2.2472","0.4996","107.0076"
"","88.3400","2.9419","2.2502","0.4977","107.1533"
"","88.4800","2.9467","2.2541","0.5012","107.3369"
"","88.6200","2.9513","2.2577","0.4992","107.5087"
"","88.7600","2.9561","2.2614","0.5024","107.6841"
"","88.9000","2.9607","2.2649","0.5008","107.8538"
"","89.0400","2.9652","2.2683","0.5039","108.0137"
"","89.1800","2.9700","2.2722","0.5024","108.1987"
"","89.3200","2.9747","2.2757","0.5056","108.3655"
"","89.4600","2.9794","2.2794","0.5039","108.5410"
"","89.6000","2.9840","2.2828","0.5071","108.7050"
"","89.7400","2.9887","2.2864","0.5060","108.8751"
"","89.8800","2.9934","2.2902","0.5085","109.0561"
"","90.0200","2.9980","2.2935","0.5094","109.2124"
"","90.1410","3.0019","2.2965","0.5125","109.3580"
"","90.2810","3.0021","2.2928","0.5126","109.1803"
"","90.4210","3.0020","2.2893","0.5126","109.0165"
"","90.5610","3.0020","2.2862","0.5125","108.8662"
"","90.7010","3.0019","2.2831","0.5125","108.7210"
"","90.8410","3.0018","2.2803","0.5124","108.5871"
"","90.9810","3.0017","2.2777","0.5124","108.4636"
"","91.1210","3.0017","2.2751","0.5124","108.3400"
"","91.2610","3.0016","2.2728","0.5123","108.2276"
"","91.4010","3.0016","2.2705","0.5123","108.1203"
"","91.5410","3.0016","2.2683","0.5123","108.0159"
"","91.6810","3.0015","2.2662","0.5123","107.9129"
"","91.8210","3.0015","2.2643","0.5123","107.8221"
"","91.9610","3.0015","2.2622","0.5123","107.7257"
"","92.1010","3.0015","2.2603","0.5123","107.6329"
"","92.2410","3.0015","2.2587","0.5122","107.5565"
"","92.3810","3.0015","2.2570","0.5122","107.4743"
"","92.5210","3.0015","2.2553","0.5122","107.3953"
"","92.6610","3.0015","2.2535","0.5122","107.3118"
"","92.8010","3.0015","2.2520","0.5122","107.2373"
"","92.9410","3.0015","2.2506","0.5122","107.1733"
"","93.0810","3.0015","2.2492","0.5122","107.1059"
"","93.2210","3.0015","2.2477","0.5122","107.0318"
"","93.3610","3.0015","2.2464","0.5122","106.9705"
"","93.5010","3.0015","2.2451","0.5122","106.9117"
"","93.6410","3.0015","2.2438","0.5122","106.8462"
"","93.7810","3.0015","2.2424","0.5122","106.7830"
"","93.9210","3.0015","2.2412","0.5122","106.7251"
"","94.0610","3.0015","2.2400","0.5122","106.6665"
"","94.2010","3.0015","2.2389","0.5122","106.6149"
"","94.3410","3.0015","2.2378","0.5122","106.5638"
"","94.4810","3.0015","2.2364","0.5122","106.4957"
"","94.6210","3.0015","2.2352","0.5122","106.4374"
"","94.7610","3.0015","2.2340","0.5122","106.3799"
"","94.9010","3.0015","2.2330","0.5122","106.3318"
"","95.0410","3.0015","2.2320","0.5122","106.2878"
"","95.1810","3.0015","2.2310","0.5122","106.2374"
"","95.3210","3.0015","2.2300","0.5122","106.1909"
"","95.4610","3.0015","2.2291","0.5122","106.1475"
"","95.6010","3.0015","2.2282","0.5122","106.1031"
"","95.7410","3.0015","2.2272","0.5122","106.0578"
"","95.8810","3.0015","2.2263","0.5122","106.0148"
"","96.0210","3.0015","2.2253","0.5122","105.9683"
"","96.1610","3.0015","2.2245","0.5122","105.9288"
"","96.3010","3.0015","2.2236","0.5122","105.8860"
"","96.4410","3.0015","2.2229","0.5122","105.8524"
"","96.5810","3.0015","2.2220","0.5122","105.8117"
"","96.7210","3.0015","2.2211","0.5122","105.7683"
"","96.8610","3.0015","2.2204","0.5122","105.7312"
"","97.0010","3.0015","2.2196","0.5122","105.6967"
"","97.1410","3.0015","2.2188","0.5122","105.6575"
"","97.2810","3.0015","2.2181","0.5122","105.6242"
"","97.4210","3.0015","2.2172","0.5122","105.5825"
"","97.5130","3.0015","2.2167","0.5123","105.5597"
"","97.6530","3.0047","2.2212","0.5141","105.7713"
"","97.7930","3.0095","2.2286","0.5169","106.1253"
"","97.9330","3.0141","2.2353","0.5196","106.4426"
"","98.0730","3.0189","2.2422","0.5224","106.7716"
"","98.2130","3.0234","2.2483","0.5250","107.0616"
"","98.3530","3.0280","2.2548","0.5277","107.3723"
"","98.4930","3.0328","2.2612","0.5305","107.6756"
"","98.6330","3.0374","2.2673","0.5332","107.9684"
"","98.7730","3.0421","2.2735","0.5359","108.2626"
"","98.9130","3.0467","2.2794","0.5386","108.5436"
"","99.0530","3.0515","2.2855","0.5414","108.8352"
"","99.1930","3.0561","2.2913","0.5441","109.1079"
"","99.3330","3.0607","2.2969","0.5468","109.3769"
"","99.4730","3.0654","2.3025","0.5496","109.6435"
"","99.6130","3.0701","2.3082","0.5523","109.9135"
"","99.7530","3.0749","2.3138","0.5551","110.1790"
"","99.8930","3.0795","2.3190","0.5578","110.4306"
"","100.0330","3.0840","2.3242","0.5604","110.6759"
"","100.1730","3.0887","2.3296","0.5631","110.9340"
"","100.3130","3.0933","2.3346","0.5658","111.1731"
"","100.4530","3.0982","2.3403","0.5687","111.4434"
"","100.5930","3.1027","2.3451","0.5713","111.6709"
"","100.7330","3.1075","2.3504","0.5741","111.9239"
"","100.8730","3.1121","2.3553","0.5768","112.1554"
"","101.0130","3.1168","2.3604","0.5795","112.3998"
"","101.1530","3.1214","2.3652","0.5822","112.6282"
"","101.2930","3.1260","2.3699","0.5849","112.8517"
"","101.4330","3.1308","2.3751","0.5877","113.1019"
"","101.5730","3.1355","2.3798","0.5904","113.3260"
"","101.7130","3.1402","2.3847","0.5932","113.5567"
"","101.8530","3.1447","2.3891","0.5958","113.7671"
"","101.9930","3.1493","2.3936","0.5985","113.9809"
"","102.1330","3.1542","2.3985","0.6013","114.2146"
"","102.2730","3.1588","2.4030","0.6040","114.4308"
"","102.4130","3.1635","2.4076","0.6067","114.6455"
"","102.5530","3.1681","2.4120","0.6094","114.8592"
"","102.6930","3.1728","2.4165","0.6122","115.0708"
"","102.8330","3.1775","2.4209","0.6149","115.2809"
"","102.9730","3.1820","2.4251","0.6175","115.4829"
"","103.1130","3.1868","2.4296","0.6203","115.6942"
"","103.2530","3.1914","2.4339","0.6230","115.9010"
"","103.3930","3.1962","2.4383","0.6258","116.1100"
"","103.5330","3.2008","2.4426","0.6285","116.3127"
"","103.6730","3.2054","2.4466","0.6312","116.5037"
"","103.8130","3.2101","2.4507","0.6339","116.6999"
"","103.9530","3.2147","2.4548","0.6366","116.8966"
"","104.0930","3.2195","2.4590","0.6394","117.0970"
"","104.2330","3.2240","2.4629","0.6421","117.2808"
"","104.3730","3.2287","2.4671","0.6448","117.4823"
"","104.5130","3.2335","2.4713","0.6476","117.6798"
"","104.6530","3.2381","2.4752","0.6503","117.8660"
"","104.7930","3.2428","2.4791","0.6530","118.0532"
"","104.9330","3.2474","2.4830","0.6557","118.2373"
"","105.0730","3.2522","2.4870","0.6585","118.4268"
"","105.2130","3.2568","2.4910","0.6612","118.6201"
"","105.3530","3.2615","2.4947","0.6639","118.7959"
"","105.4930","3.2661","2.4985","0.6666","118.9785"
"","105.6330","3.2707","2.5024","0.6693","119.1618"
"","105.7730","3.2755","2.5065","0.6721","119.3574"
"","105.9130","3.2801","2.5102","0.6748","119.5313"
"","106.0530","3.2848","2.5140","0.6775","119.7135"
"","106.1930","3.2894","2.5179","0.6802","119.8993"
"","106.3330","3.2941","2.5216","0.6829","120.0767"
"","106.4730","3.2988","2.5253","0.6857","120.2542"
"","106.6130","3.3033","2.5288","0.6883","120.4173"
"","106.7530","3.3081","2.5327","0.6911","120.6027"
"","106.8930","3.3127","2.5364","0.6938","120.7830"
"","107.0330","3.3175","2.5403","0.6966","120.9663"
"","107.1730","3.3222","2.5440","0.6993","121.1452"
"","107.3130","3.3266","2.5475","0.7019","121.3081"
"","107.4530","3.3314","2.5513","0.7047","121.4894"
"","107.5930","3.3360","2.5549","0.7074","121.6638"
"","107.7330","3.3409","2.5589","0.7102","121.8522"
"","107.8730","3.3454","2.5624","0.7128","122.0171"
"","108.0130","3.3501","2.5661","0.7156","122.1944"
"","108.1530","3.3548","2.5699","0.7184","122.3764"
"","108.2930","3.3594","2.5733","0.7210","122.5405"
"","108.4330","3.3641","2.5771","0.7237","122.7183"
"","108.5730","3.3687","2.5806","0.7264","122.8845"
"","108.7130","3.3735","2.5846","0.7292","123.0753"
"","108.8530","3.3782","2.5884","0.7320","123.2578"
"","108.9930","3.3828","2.5918","0.7346","123.4183"
"","109.1330","3.3874","2.5956","0.7374","123.5980"
"","109.2730","3.3920","2.5991","0.7400","123.7661"
"","109.4130","3.3968","2.6028","0.7428","123.9447"
"","109.5530","3.4015","2.6066","0.7456","124.1229"
"","109.6930","3.4060","2.6100","0.7482","124.2880"
"","109.8330","3.4108","2.6138","0.7510","124.4669"
"","109.9730","3.4154","2.6175","0.7537","124.6413"
"","110.1130","3.4201","2.6210","0.7564","124.8121"
"","110.2530","3.4247","2.6244","0.7591","124.9734"
"","110.3930","3.4294","2.6282","0.7619","125.1548"
"","110.5330","3.4342","2.6319","0.7646","125.3311"
"","110.6730","3.4388","2.6355","0.7673","125.4987"
"","110.8130","3.4435","2.6392","0.7700","125.6746"
"","110.9530","3.4480","2.6425","0.7727","125.8315"
[...]
"","149.8000","4.9908","6.0202","0.0160","101.2630"
"","150.0760","5.0000","6.0277","0.0171","101.3880"
"","150.3370","5.0018","6.0129","0.0181","101.1397"
"","150.6170","5.0017","5.9938","0.0180","100.8176"
"","150.8970","5.0015","5.9768","0.0179","100.5324"
"","151.1770","5.0014","5.9616","0.0179","100.2766"
"","151.4570","5.0013","5.9476","0.0178","100.0419"
"","151.7370","5.0013","5.9348","0.0178","99.8256"
"","152.0170","5.0013","5.9229","0.0178","99.6250"
"","152.2970","5.0012","5.9119","0.0178","99.4399"
"","152.5770","5.0012","5.9012","0.0178","99.2611"
"","152.8570","5.0012","5.8915","0.0178","99.0971"
"","153.1370","5.0012","5.8822","0.0178","98.9405"
"","153.4170","5.0012","5.8734","0.0178","98.7925"
"","153.6970","5.0012","5.8650","0.0178","98.6513"
"","153.9770","5.0012","5.8568","0.0178","98.5142"
"","154.2570","5.0012","5.8492","0.0178","98.3858"
"","154.5370","5.0012","5.8417","0.0178","98.2593"
"","154.8170","5.0012","5.8344","0.0178","98.1375"
"","155.0970","5.0012","5.8277","0.0178","98.0241"
"","155.3770","5.0012","5.8212","0.0178","97.9152"
"","155.6570","5.0012","5.8150","0.0178","97.8105"
"","155.9370","5.0012","5.8087","0.0178","97.7045"
"","156.2170","5.0012","5.8029","0.0178","97.6074"
"","156.4970","5.0012","5.7972","0.0178","97.5113"
"","156.7770","5.0012","5.7917","0.0178","97.4192"
"","157.0340","5.0046","5.7976","0.0197","97.5173"
"","157.3140","5.0139","5.8227","0.0252","97.9408"
"","157.5940","5.0234","5.8470","0.0307","98.3490"
"","157.8740","5.0326","5.8688","0.0361","98.7165"
"","158.1540","5.0420","5.8903","0.0415","99.0772"
"","158.4340","5.0512","5.9102","0.0469","99.4120"
"","158.7140","5.0606","5.9294","0.0524","99.7356"
"","158.9940","5.0699","5.9478","0.0578","100.0453"
"","159.2740","5.0794","5.9660","0.0634","100.3512"
"","159.5540","5.0886","5.9828","0.0688","100.6327"
"","159.8340","5.0979","5.9990","0.0741","100.9058"
"","160.1140","5.1072","6.0151","0.0796","101.1761"
"","160.3940","5.1166","6.0303","0.0850","101.4326"
"","160.6740","5.1259","6.0449","0.0905","101.6773"
"","160.9540","5.1353","6.0592","0.0960","101.9191"
"","161.2340","5.1447","6.0732","0.1015","102.1542"
"","161.5140","5.1538","6.0858","0.1068","102.3651"
"","161.7940","5.1633","6.0988","0.1123","102.5853"
"","162.0740","5.1726","6.1109","0.1177","102.7876"
"","162.3540","5.1819","6.1230","0.1232","102.9915"
"","162.6340","5.1912","6.1345","0.1286","103.1843"
"","162.9140","5.2007","6.1463","0.1341","103.3831"
"","163.1940","5.2100","6.1566","0.1395","103.5560"
"","163.4740","5.2192","6.1668","0.1449","103.7283"
"","163.7540","5.2286","6.1771","0.1504","103.9018"
"","164.0340","5.2379","6.1870","0.1558","104.0687"
"","164.3140","5.2473","6.1970","0.1613","104.2364"
"","164.5940","5.2567","6.2064","0.1668","104.3935"
"","164.8740","5.2661","6.2159","0.1723","104.5535"
"","165.1540","5.2752","6.2239","0.1776","104.6894"
"","165.4340","5.2846","6.2329","0.1830","104.8407"
"","165.7140","5.2939","6.2414","0.1885","104.9827"
"","165.9940","5.3033","6.2502","0.1940","105.1305"
"","166.2740","5.3126","6.2581","0.1994","105.2634"
"","166.5540","5.3220","6.2666","0.2049","105.4077"
"","166.8340","5.3312","6.2739","0.2102","105.5293"
"","167.1140","5.3405","6.2819","0.2157","105.6637"
"","167.3940","5.3499","6.2895","0.2211","105.7919"
"","167.6740","5.3593","6.2973","0.2266","105.9231"
"","167.9540","5.3686","6.3048","0.2320","106.0489"
"","168.2340","5.3780","6.3126","0.2375","106.1800"
"","168.5140","5.3874","6.3199","0.2430","106.3028"
"","168.7940","5.3965","6.3266","0.2483","106.4169"
"","169.0740","5.4060","6.3343","0.2538","106.5458"
"","169.3540","5.4153","6.3414","0.2593","106.6645"
"","169.6340","5.4247","6.3487","0.2647","106.7884"
"","169.9140","5.4340","6.3556","0.2702","106.9047"
"","170.1940","5.4434","6.3628","0.2757","107.0252"
"","170.4740","5.4525","6.3691","0.2810","107.1307"
"","170.7540","5.4619","6.3761","0.2865","107.2491"
"","171.0340","5.4712","6.3830","0.2919","107.3649"
"","171.3140","5.4807","6.3902","0.2974","107.4851"
"","171.5940","5.4899","6.3965","0.3028","107.5926"
"","171.8740","5.4993","6.4036","0.3083","107.7106"
"","172.1540","5.5086","6.4102","0.3137","107.8223"
"","172.4340","5.5178","6.4166","0.3191","107.9296"
"","172.7140","5.5273","6.4237","0.3246","108.0487"
"","172.9940","5.5366","6.4302","0.3300","108.1592"
"","173.2740","5.5460","6.4371","0.3355","108.2745"
"","173.5540","5.5553","6.4436","0.3409","108.3837"
"","173.8340","5.5647","6.4503","0.3464","108.4973"
"","174.1140","5.5738","6.4561","0.3517","108.5951"
"","174.3940","5.5832","6.4629","0.3572","108.7085"
"","174.6740","5.5926","6.4696","0.3627","108.8212"
"","174.9540","5.6021","6.4766","0.3682","108.9399"
"","175.2340","5.6113","6.4825","0.3736","109.0388"
"","175.5140","5.6207","6.4891","0.3791","109.1493"
"","175.7940","5.6299","6.4952","0.3845","109.2528"
"","176.0740","5.6392","6.5016","0.3898","109.3593"
"","176.3540","5.6487","6.5086","0.3954","109.4775"
"","176.6340","5.6580","6.5149","0.4008","109.5837"
"","176.9140","5.6673","6.5212","0.4063","109.6892"
"","177.1940","5.6766","6.5273","0.4117","109.7926"
"","177.4740","5.6860","6.5342","0.4172","109.9075"
"","177.7540","5.6951","6.5398","0.4225","110.0019"
"","178.0340","5.7046","6.5467","0.4280","110.1177"
"","178.3140","5.7139","6.5529","0.4335","110.2222"
"","178.5940","5.7233","6.5594","0.4389","110.3316"
"","178.8740","5.7326","6.5653","0.4443","110.4318"
"","179.1540","5.7420","6.5715","0.4498","110.5357"
"","179.4340","5.7512","6.5775","0.4552","110.6357"
"","179.7140","5.7605","6.5836","0.4606","110.7397"
"","179.9940","5.7700","6.5903","0.4661","110.8515"
"","180.2740","5.7794","6.5968","0.4716","110.9616"
"","180.5540","5.7886","6.6026","0.4770","111.0592"
"","180.8340","5.7979","6.6086","0.4825","111.1604"
"","181.1140","5.8073","6.6150","0.4879","111.2668"
"","181.3940","5.8165","6.6207","0.4933","111.3624"
"","181.6740","5.8260","6.6276","0.4988","111.4784"
"","181.9540","5.8353","6.6336","0.5043","111.5803"
"","182.2340","5.8447","6.6398","0.5097","111.6837"
"","182.5140","5.8539","6.6452","0.5151","111.7758"
"","182.7940","5.8633","6.6517","0.5206","111.8841"
"","183.0740","5.8726","6.6575","0.5260","111.9823"
"","183.3540","5.8819","6.6635","0.5314","112.0831"
"","183.6340","5.8913","6.6697","0.5369","112.1871"
"","183.9140","5.9007","6.6759","0.5424","112.2923"
"","184.1940","5.9099","6.6819","0.5478","112.3918"
"","184.4740","5.9193","6.6879","0.5532","112.4931"
"","184.7540","5.9287","6.6942","0.5587","112.5989"
"","185.0340","5.9378","6.6996","0.5641","112.6894"
"","185.3140","5.9473","6.7062","0.5696","112.8006"
"","185.5940","5.9566","6.7121","0.5750","112.8999"
"","185.8740","5.9660","6.7180","0.5805","112.9992"
"","186.1540","5.9752","6.7235","0.5858","113.0922"
"","186.4340","5.9846","6.7297","0.5913","113.1962"
"","186.7140","5.9939","6.7355","0.5967","113.2933"
"","186.9940","6.0033","6.7419","0.6022","113.4020"
"","187.2740","6.0127","6.7475","0.6077","113.4966"
"","187.5540","6.0220","6.7535","0.6131","113.5962"
"","187.8340","6.0312","6.7588","0.6185","113.6868"
"","188.1140","6.0406","6.7650","0.6240","113.7894"
"","188.3940","6.0501","6.7711","0.6295","113.8935"
"","188.6740","6.0593","6.7766","0.6349","113.9856"
"","188.9540","6.0687","6.7825","0.6404","114.0850"
"","189.2340","6.0780","6.7881","0.6458","114.1782"
"","189.5140","6.0873","6.7937","0.6512","114.2725"
"","189.7940","6.0965","6.7992","0.6566","114.3650"
"","190.0740","6.1060","6.8055","0.6621","114.4712"
"","190.3540","6.1152","6.8105","0.6675","114.5559"
"","190.6340","6.1247","6.8167","0.6730","114.6593"
"","190.9140","6.1339","6.8221","0.6784","114.7513"
"","191.1940","6.1432","6.8279","0.6839","114.8490"
"","191.4740","6.1525","6.8332","0.6893","114.9375"
"","191.7540","6.1619","6.8391","0.6947","115.0359"
"","192.0340","6.1713","6.8450","0.7002","115.1367"
"","192.3140","6.1806","6.8505","0.7056","115.2289"
"","192.5940","6.1900","6.8565","0.7112","115.3292"
"","192.8740","6.1993","6.8617","0.7165","115.4176"
"","193.1540","6.2086","6.8670","0.7220","115.5059"
"","193.4340","6.2179","6.8725","0.7274","115.5992"
"","193.7140","6.2274","6.8787","0.7329","115.7025"
"","193.9940","6.2366","6.8836","0.7383","115.7858"
"","194.2740","6.2460","6.8893","0.7438","115.8808"
"","194.5540","6.2552","6.8946","0.7492","115.9696"
"","194.8340","6.2646","6.9001","0.7546","116.0633"
"","195.1140","6.2738","6.9051","0.7600","116.1473"
"","195.3940","6.2833","6.9109","0.7655","116.2451"
"","195.6740","6.2927","6.9164","0.7710","116.3373"
"","195.9540","6.3019","6.9216","0.7764","116.4244"
"","196.2340","6.3113","6.9272","0.7819","116.5183"
"","196.5140","6.3206","6.9324","0.7873","116.6059"
"","196.7940","6.3299","6.9376","0.7927","116.6935"
"","197.0740","6.3392","6.9429","0.7982","116.7826"
"","197.3540","6.3487","6.9487","0.8037","116.8799"
"","197.6340","6.3579","6.9534","0.8091","116.9586"
"","197.9140","6.3673","6.9590","0.8145","117.0526"
"","198.1940","6.3765","6.9639","0.8199","117.1365"
"","198.4740","6.3859","6.9692","0.8254","117.2251"
"","198.7540","6.3952","6.9743","0.8308","117.3109"
"","199.0340","6.4047","6.9802","0.8363","117.4100"
"","199.3140","6.4140","6.9853","0.8418","117.4958"
"","199.5940","6.4233","6.9903","0.8472","117.5791"
"","199.8740","6.4326","6.9955","0.8526","117.6666"
"","200.1540","6.4419","7.0008","0.8581","117.7563"
"","200.4340","6.4513","7.0059","0.8635","117.8429"
"","200.7140","6.4606","7.0113","0.8690","117.9330"
"","200.9940","6.4701","7.0166","0.8745","118.0227"
"","201.2740","6.4792","7.0212","0.8798","118.0996"
"","201.5540","6.4886","7.0266","0.8853","118.1900"
"","201.8340","6.4979","7.0313","0.8907","118.2700"
"","202.1140","6.5072","7.0366","0.8962","118.3593"
"","202.3940","6.5165","7.0416","0.9016","118.4421"
"","202.6740","6.5260","7.0472","0.9071","118.5367"
"","202.9540","6.5353","7.0520","0.9125","118.6171"
"","203.2340","6.5446","7.0568","0.9179","118.6991"
"","203.5140","6.5539","7.0617","0.9234","118.7815"
"","203.7940","6.5632","7.0668","0.9288","118.8671"
"","204.0740","6.5726","7.0718","0.9343","118.9511"
"","204.3540","6.5820","7.0772","0.9398","119.0418"
"","204.6340","6.5914","7.0823","0.9453","119.1268"
"","204.9140","6.6005","7.0864","0.9506","119.1966"
"","205.1940","6.6099","7.0914","0.9561","119.2805"
"","205.4740","6.6192","7.0962","0.9615","119.3620"
"","205.7540","6.6286","7.1013","0.9670","119.4470"
"","206.0340","6.6379","7.1061","0.9724","119.5271"
"","206.3140","6.6474","7.1112","0.9779","119.6142"
"","206.5940","6.6566","7.1155","0.9833","119.6861"
"","206.8740","6.6659","7.1202","0.9887","119.7655"
"","207.1540","6.6752","7.1250","0.9941","119.8454"
"","207.4340","6.6846","7.1298","0.9996","119.9260"
"","207.7140","6.6940","7.1346","1.0051","120.0078"
"","207.9940","6.7034","7.1397","1.0106","120.0923"
"","208.2740","6.7127","7.1445","1.0160","120.1734"
"","208.5540","6.7219","7.1486","1.0214","120.2424"
"","208.8340","6.7312","7.1533","1.0268","120.3219"
"","209.1140","6.7406","7.1581","1.0322","120.4021"
"","209.3940","6.7500","7.1631","1.0377","120.4869"
"","209.6740","6.7593","7.1675","1.0432","120.5600"
"","209.9540","6.7687","7.1723","1.0487","120.6409"
"","210.2340","6.7779","7.1761","1.0540","120.7044"
"","210.5140","6.7872","7.1807","1.0594","120.7819"
"","210.7940","6.7965","7.1852","1.0649","120.8579"
"","211.0740","6.8059","7.1900","1.0704","120.9393"
"","211.3540","6.8153","7.1944","1.0758","121.0123"
"","211.6340","6.8247","7.1991","1.0813","121.0925"
"","211.9140","6.8341","7.2034","1.0868","121.1644"
"","212.1940","6.8432","7.2073","1.0921","121.2307"
"","212.4740","6.8527","7.2122","1.0976","121.3121"
"","212.7540","6.8619","7.2165","1.1031","121.3841"
"","213.0340","6.8714","7.2211","1.1085","121.4627"
"","213.3140","6.8806","7.2253","1.1140","121.5325"
"","213.5940","6.8900","7.2299","1.1194","121.6108"
"","213.8740","6.8992","7.2336","1.1248","121.6715"
"","214.1540","6.9086","7.2380","1.1302","121.7457"
"","214.4340","6.9179","7.2423","1.1357","121.8188"
"","214.7140","6.9273","7.2467","1.1412","121.8934"
"","214.9940","6.9366","7.2507","1.1466","121.9597"
"","215.2740","6.9460","7.2549","1.1521","122.0308"
"","215.5540","6.9552","7.2588","1.1575","122.0954"
"","215.8340","6.9645","7.2627","1.1629","122.1622"
"","216.1140","6.9739","7.2671","1.1684","122.2361"
"","216.3940","6.9833","7.2714","1.1738","122.3077"
"","216.6740","6.9926","7.2754","1.1793","122.3757"
"","216.9540","7.0019","7.2794","1.1847","122.4423"
"","217.2340","7.0113","7.2836","1.1902","122.5126"
"","217.5140","7.0204","7.2868","1.1955","122.5676"
"","217.7940","7.0299","7.2913","1.2010","122.6433"
"","218.0740","7.0393","7.2955","1.2065","122.7131"
"","218.3540","7.0487","7.2997","1.2120","122.7835"
"","218.6340","7.0579","7.3033","1.2174","122.8441"
"","218.9140","7.0673","7.3075","1.2228","122.9155"
"","219.1940","7.0766","7.3111","1.2282","122.9754"
"","219.4740","7.0859","7.3149","1.2337","123.0399"
"","219.7540","7.0953","7.3192","1.2392","123.1114"
"","220.0340","7.1047","7.3230","1.2446","123.1768"
"","220.3140","7.1140","7.3268","1.2501","123.2394"
"","220.5940","7.1233","7.3305","1.2555","123.3016"
"","220.8740","7.1327","7.3343","1.2610","123.3662"
"","221.1540","7.1418","7.3373","1.2663","123.4170"
"","221.4340","7.1513","7.3415","1.2718","123.4865"
"","221.7140","7.1606","7.3452","1.2772","123.5492"
"","221.9940","7.1700","7.3490","1.2827","123.6126"
"","222.2740","7.1792","7.3521","1.2881","123.6660"
"","222.5540","7.1886","7.3556","1.2936","123.7243"
"","222.8340","7.1979","7.3588","1.2990","123.7782"
"","223.1140","7.2072","7.3622","1.3044","123.8360"
"","223.3940","7.2166","7.3658","1.3099","123.8963"
"","223.6740","7.2260","7.3693","1.3154","123.9556"
"","223.9540","7.2353","7.3726","1.3208","124.0104"
"","224.2340","7.2446","7.3758","1.3262","124.0639"
"","224.5140","7.2540","7.3790","1.3317","124.1175"
"","224.7940","7.2632","7.3816","1.3371","124.1612"
"","225.0740","7.2727","7.3853","1.3426","124.2240"
"","225.3540","7.2820","7.3880","1.3481","124.2698"
"","225.6340","7.2913","7.3910","1.3535","124.3205"
"","225.9140","7.3005","7.3936","1.3588","124.3634"
"","226.1940","7.3099","7.3966","1.3644","124.4132"
"","226.4740","7.3192","7.3991","1.3698","124.4562"
"","226.7540","7.3286","7.4016","1.3752","124.4974"
"","227.0340","7.3380","7.4043","1.3807","124.5436"
"","227.3140","7.3473","7.4068","1.3861","124.5856"
"","227.5940","7.3566","7.4082","1.3915","124.6092"
"","227.8740","7.3660","7.4104","1.3970","124.6467"
"","228.1540","7.3753","7.4126","1.4025","124.6833"
"","228.4340","7.3845","7.4146","1.4078","124.7165"
"","228.7140","7.3940","7.4171","1.4134","124.7582"
"","228.9940","7.4033","7.4190","1.4188","124.7913"
"","229.2740","7.4126","7.4211","1.4242","124.8257"
"","229.5540","7.4218","7.4225","1.4296","124.8499"
"","229.8340","7.4313","7.4245","1.4351","124.8828"
"","230.1140","7.4406","7.4259","1.4405","124.9068"
"","230.3940","7.4500","7.4277","1.4460","124.9376"
"","230.6740","7.4593","7.4292","1.4515","124.9615"
"","230.9540","7.4686","7.4303","1.4569","124.9808"
"","231.2340","7.4778","7.4312","1.4623","124.9958"
"","231.5140","7.4873","7.4322","1.4678","125.0130"
"","231.7940","7.4967","7.4332","1.4733","125.0292"
"","232.0740","7.5059","7.4334","1.4787","125.0326"
"","232.3540","7.5154","7.4343","1.4842","125.0477"
"","232.6340","7.5246","7.4337","1.4895","125.0385"
"","232.9140","7.5339","7.4332","1.4950","125.0294"
"","233.1940","7.5432","7.4324","1.5004","125.0168"
"","233.4740","7.5527","7.4319","1.5059","125.0077"
"","233.7540","7.5619","7.4304","1.5113","124.9830"
"","234.0340","7.5713","7.4293","1.5168","124.9647"
"","234.3140","7.5806","7.4275","1.5222","124.9343"
"","234.5940","7.5899","7.4255","1.5277","124.9007"
"","234.8740","7.5992","7.4229","1.5330","124.8568"
"","235.1540","7.6086","7.4205","1.5385","124.8156"
"","235.4340","7.6180","7.4170","1.5440","124.7571"
"","235.7140","7.6273","7.4106","1.5494","124.6498"
"","235.9940","7.6367","7.4036","1.5549","124.5313"
"","236.2740","7.6459","7.3946","1.5603","124.3812"
"","236.5540","7.6552","7.3844","1.5657","124.2092"
"","236.8340","7.6646","7.3721","1.5712","124.0014"
"","237.1140","7.6741","7.3576","1.5767","123.7581"
"","237.3940","7.6833","7.3314","1.5821","123.3176"
"","237.6740","7.6927","7.2998","1.5876","122.7862"
"","237.9540","7.7019","7.2581","1.5930","122.0836"
"","238.2340","7.7113","7.1993","1.5984","121.0955"
"","238.5140","7.7205","7.0237","1.6038","118.1422"
"","238.5940","7.7237","5.0611","1.6057","85.1306"
"","238.8240","7.7313","4.3936","1.6101","73.9029"
"","239.1040","7.7404","4.2834","1.6154","72.0486"
"","239.3840","7.7495","4.2138","1.6207","70.8778"
"","239.6640","7.7589","4.1666","1.6262","70.0833"
"","239.9440","7.7683","4.1302","1.6317","69.4716"
"","240.2240","7.7776","4.1011","1.6371","68.9819"
"","240.5040","7.7870","4.0809","1.6426","68.6418"
"","240.7840","7.7964","4.0673","1.6481","68.4140"
"","241.0640","7.8056","4.0533","1.6534","68.1775"
"","241.3440","7.8150","4.0421","1.6589","67.9893"
"","241.6240","7.8242","4.0300","1.6643","67.7865"
"","241.9040","7.8336","4.0201","1.6698","67.6206"
"","242.1840","7.8429","4.0075","1.6752","67.4081"
"","242.4640","7.8524","3.9996","1.6808","67.2745"
"","242.7440","7.8616","3.9907","1.6861","67.1261"
"","243.0240","7.8709","3.9794","1.6915","66.9352"
"","243.3040","7.8802","3.9496","1.6970","66.4338"
"","243.5840","7.8896","3.9253","1.7024","66.0256"
"","243.8640","7.8990","3.9114","1.7079","65.7914"
"","244.1440","7.9084","3.9036","1.7134","65.6602"
"","244.4240","7.9177","3.8980","1.7188","65.5667"
"","244.7040","7.9268","3.8938","1.7242","65.4955"
"","244.9840","7.9363","3.8910","1.7297","65.4490"
"","245.2640","7.9456","3.8893","1.7351","65.4198"
"","245.5440","7.9550","3.8884","1.7406","65.4046"
"","245.8240","7.9643","3.8862","1.7460","65.3678"
"","246.1040","7.9737","3.8792","1.7515","65.2496"
"","246.3840","7.9829","3.8714","1.7569","65.1187"
"","246.6640","7.9922","3.8639","1.7623","64.9924"
"","246.9440","8.0015","3.8575","1.7677","64.8856"
"","247.2240","8.0109","3.8499","1.7732","64.7566"
"","247.5040","8.0203","3.8404","1.7787","64.5972"
"","247.7840","8.0297","3.8322","1.7842","64.4593"
"","248.0640","8.0391","3.8238","1.7896","64.3172"
"","248.3440","8.0482","3.8155","1.7949","64.1788"
"","248.6240","8.0576","3.8076","1.8004","64.0459"
"","248.9040","8.0669","3.7997","1.8059","63.9132"
"","249.1840","8.0764","3.7911","1.8114","63.7682"
"","249.4640","8.0856","3.7810","1.8168","63.5983"
"","249.7440","8.0950","3.7708","1.8223","63.4269"
"","250.0240","8.1042","3.7566","1.8276","63.1880"
"","250.3040","8.1136","3.7349","1.8331","62.8226"
"","250.5840","8.1229","3.7151","1.8385","62.4889"
"","250.8640","8.1323","3.6934","1.8440","62.1240"
"","251.1440","8.1416","3.6480","1.8494","61.3611"
"","251.4240","8.1510","3.6090","1.8549","60.7045"
"","251.7040","8.1603","3.5539","1.8603","59.7783"
"","251.9840","8.1696","3.4871","1.8657","58.6553"
"","252.2640","8.1790","3.4023","1.8712","57.2276"
"","252.5440","8.1883","3.2541","1.8767","54.7358"
"","252.8240","8.1977","3.0767","1.8821","51.7510"
"","253.1040","8.2070","2.7918","1.8876","46.9594"
"","253.3840","8.2164","2.5248","1.8931","42.4685"
"","253.6640","8.2255","2.2802","1.8984","38.3545"
"","253.9440","8.2349","2.0697","1.9039","34.8128"
"","254.2240","8.2443","1.8726","1.9093","31.4973"
"","254.5040","8.2538","1.7837","1.9148","30.0029"
"","254.7840","8.2630","1.7080","1.9202","28.7286"
"","255.0640","8.2723","1.6472","1.9257","27.7064"
"","255.3440","8.2816","1.6001","1.9311","26.9138"
"","255.6240","8.2909","1.4832","1.9365","24.9488"
"","255.9040","8.3004","1.3987","1.9420","23.5274"
"","256.1840","8.3097","1.2658","1.9475","21.2912"
"","256.4440","8.3185","0.4471","1.9526","7.5203"
"","256.7240","8.3276","0.3982","1.9579","6.6974"
"","257.0040","8.3370","0.3759","1.9634","6.3223"
"","257.1340","8.3413","0.3717","1.9659","6.2523"